Workbook
Name БонусНПД: НАСТРОЙКИ!$B$18
Name Виды: СПРАВОЧНИКИ!$J$7:$J$13
Name ВычетУСН: НАСТРОЙКИ!$B$22
Name Год: НАСТРОЙКИ!$B$9
Name ДатаОтчета: НАСТРОЙКИ!$B$10
Name ДоходПрошлыйГод: НАСТРОЙКИ!$B$21
Name Категории: СПРАВОЧНИКИ!$F$7:$F$66
Name Контрагенты: СПРАВОЧНИКИ!$G$7:$G$66
Name ЛимитНПД: НАЛОГИ!$B$39
Name ЛимитУСН: НАЛОГИ!$B$41
Name МаксВзносы: НАСТРОЙКИ!$B$20
Name МесяцыРезерва: НАСТРОЙКИ!$B$24
Name НачалоУчета: НАСТРОЙКИ!$B$11
Name ПорогНДС: НАЛОГИ!$B$40
Name Проекты: СПРАВОЧНИКИ!$I$7:$I$66
Name Режим: НАСТРОЙКИ!$B$8
Name РежимыИП: СПРАВОЧНИКИ!$K$7:$K$10
Name РежимыООО: СПРАВОЧНИКИ!$L$7:$L$9
Name Сотрудники: НАСТРОЙКИ!$B$12
Name СтавкаДоход: НАСТРОЙКИ!$B$14
Name СтавкаДР: НАСТРОЙКИ!$B$15
Name СтавкаНПДФЛ: НАСТРОЙКИ!$B$16
Name СтавкаНПДЮЛ: НАСТРОЙКИ!$B$17
Name Сценарий: НАСТРОЙКИ!$B$23
Name Счета: СЧЕТА!$A$7:$A$16
Name Типы: СПРАВОЧНИКИ!$A$7:$A$22
Name ФиксВзносы: НАСТРОЙКИ!$B$19
Name Форма: НАСТРОЙКИ!$B$7

Sheet ПАНЕЛЬ
A1: Главная панель | D1: Настройки | F1: Контроль
A2: FINCORE BUSINESS PRO
A4: LEO STUDIO. Демонстрационный проект. Все данные вымышлены.
A5: =Форма&" · "&Режим -> ИП · УСН Доходы | F5: =TEXT(DAY(ДатаОтчета),"00")&"."&TEXT(MONTH(ДатаОтчета),"00")&"."&YEAR(ДатаОтчета)&" · RUB" -> 31.12.2026 · RUB | K5: =Сценарий -> Базовый
A7: Выручка | F7: Финансовый результат | K7: Денежные средства
A8: =ОПиУ!N7 -> 6597000 | F8: =ОПиУ!N16 -> 872197.89 | K8: =СЧЕТА!B19 -> 1675043.2
A11: Дебиторская задолженность | F11: Кредиты и займы | K11: Налоги и взносы к уплате
A12: =БАЛАНС!B8 -> 59040 | F12: =БАЛАНС!B15 -> 136028.15 | K12: =БАЛАНС!B16 -> 319657.2
A33: =БАЛАНС!B29&". Резерв: "&РЕЗЕРВЫ!B16 -> Баланс сходится. Резерв: Резерв ниже цели
A34: =НАЛОГИ!B4 -> ПРЕДВАРИТЕЛЬНЫЙ РАСЧЁТ
A35: Проверяйте лист КОНТРОЛЬ перед принятием решений. Просрочки и ошибки выделяются цветом.
A37: НАСТРОЙКИ | C37: ДДС | E37: ОПиУ | G37: БАЛАНС | I37: НАЛОГИ | K37: БЮДЖЕТ | M37: РЕЗЕРВЫ
A38: РЕИНВЕСТИЦИИ | C38: ПРОГНОЗ | E38: РИСКИ | G38: ПОКАЗАТЕЛИ | I38: АНАЛИТИКА | K38: КРЕДИТ | M38: АКТИВЫ
A39: ИНВЕСТПРОЕКТ | C39: ОПЕРАЦИИ | E39: НАЧИСЛЕНИЯ | G39: СЧЕТА | I39: СПРАВОЧНИКИ | K39: КОНТРОЛЬ | M39: ИНСТРУКЦИЯ
A41: Показатель | B41: =CHOOSE(MONTH(ОПиУ!B6),"янв","фев","мар","апр","май","июн","июл","авг","сен","окт","ноя","дек") -> янв | C41: =CHOOSE(MONTH(ОПиУ!C6),"янв","фев","мар","апр","май","июн","июл","авг","сен","окт","ноя","дек") -> фев | D41: =CHOOSE(MONTH(ОПиУ!D6),"янв","фев","мар","апр","май","июн","июл","авг","сен","окт","ноя","дек") -> мар | E41: =CHOOSE(MONTH(ОПиУ!E6),"янв","фев","мар","апр","май","июн","июл","авг","сен","окт","ноя","дек") -> апр | F41: =CHOOSE(MONTH(ОПиУ!F6),"янв","фев","мар","апр","май","июн","июл","авг","сен","окт","ноя","дек") -> май | G41: =CHOOSE(MONTH(ОПиУ!G6),"янв","фев","мар","апр","май","июн","июл","авг","сен","окт","ноя","дек") -> июн | H41: =CHOOSE(MONTH(ОПиУ!H6),"янв","фев","мар","апр","май","июн","июл","авг","сен","окт","ноя","дек") -> июл | I41: =CHOOSE(MONTH(ОПиУ!I6),"янв","фев","мар","апр","май","июн","июл","авг","сен","окт","ноя","дек") -> авг | ... M41: =CHOOSE(MONTH(ОПиУ!M6),"янв","фев","мар","апр","май","июн","июл","авг","сен","окт","ноя","дек") -> дек
A42: Выручка | B42: =ОПиУ!B7 -> 420000 | C42: =ОПиУ!C7 -> 180000 | D42: =ОПиУ!D7 -> 507000 | E42: =ОПиУ!E7 -> 550000 | F42: =ОПиУ!F7 -> 580000 | G42: =ОПиУ!G7 -> 620000 | H42: =ОПиУ!H7 -> 590000 | I42: =ОПиУ!I7 -> 210000 | ... M42: =ОПиУ!M7 -> 820000
A43: Результат | B43: =ОПиУ!B16 -> 4917.5 | C43: =ОПиУ!C16 -> -149325.34 | D43: =ОПиУ!D16 -> 49344.17 | E43: =ОПиУ!E16 -> 76696.08 | F43: =ОПиУ!F16 -> 95160.42 | G43: =ОПиУ!G16 -> 119727.22 | H43: =ОПиУ!H16 -> 101971.53 | I43: =ОПиУ!I16 -> -194651 | ... M43: =ОПиУ!M16 -> 247318.69
A44: Денежный остаток | B44: =ДДС!B14 -> 645622.77 | C44: =ДДС!C14 -> 508045.54 | D44: =ДДС!D14 -> 566868.31 | E44: =ДДС!E14 -> 635891.08 | F44: =ДДС!F14 -> 770313.85 | G44: =ДДС!G14 -> 881936.62 | H44: =ДДС!H14 -> 978159.39 | I44: =ДДС!I14 -> 795982.16 | ... M44: =ДДС!M14 -> 1675043.2

Sheet НАСТРОЙКИ
A1: Главная панель | D1: Настройки | F1: Контроль
A2: НАСТРОЙКИ
A3: LEO STUDIO • Управленческий учёт • RUB
A6: Параметр | B6: Значение | C6: Пояснение
A7: Форма бизнеса | B7: ИП | C7: ИП или ООО
A8: Налоговый режим | B8: УСН Доходы | C8: ОСНО / ПСН: только ручной режим
A9: Отчётный год | B9: 2026 | C9: Одна книга на финансовый год
A10: Дата отчёта | B10: 46387 | C10: В демо весь 2026 год — вымышленный сценарий
A11: Начало учёта | B11: 46023 | C11: Не менять без переноса начальных остатков
A12: Сотрудники | B12: Да | C12: Для ООО: взносы и НДФЛ задаются отдельно
A13: Регион | B13: Москва | C13: Региональные льготы подтвердите отдельно
A14: Ставка УСН доходы | B14: 0.06 | C14: Базовая ставка, редактируется при подтверждённой льготе
A15: Ставка УСН Д-Р | B15: 0.15 | C15: Базовая ставка, региональные условия проверяются
A16: НПД ФЛ | B16: 0.04 | C16: Поступления от физических лиц
A17: НПД ЮЛ / ИП | B17: 0.06 | C17: Поступления от организаций и ИП
A18: Остаток бонуса НПД | B18: 10000 | C18: От 0 до 10000; остаток на начало года
A19: Взносы ИП фиксированные | B19: 57390 | C19: Полный 2026 год, без специальных освобождений
A20: Дополнительные взносы максимум | B20: 321818 | C20: Только дополнительная часть 1% в 2026 году
A21: Доход прошлого года | B21: 0 | C21: Для контроля освобождения от НДС
A22: Взносы к уменьшению УСН | B22: 0 | C22: Подтверждённая сумма нарастающим итогом; без повторного вычета
A23: Выбранный сценарий | B23: Базовый | C23: Сценарий изменяет единый прогноз
A24: Месяцев резерва | B24: 3 | C24: Целевое покрытие обязательных расходов
A25: Пополнение резерва | B25: 15000 | C25: План, не является расходом
A26: План обязательных расходов | B26: 0 | C26: Если нет истории, заполнить вручную
A27: НПД условия подтверждены | B27: Нет | C27: Нет работников, запрещённых видов деятельности и прочих ограничений
A28: Автоналог разрешён | B28: Да | C28: Нет при НДС, неподдерживаемом режиме или году
A29: Фиксированные расходы в месяц | B29: 0 | C29: 0: средние операционные затраты из истории
A30: Прогноз: поступления из старой ДЗ | B30: 0 | C30: Сумма, планируемая в первом месяце прогноза
A31: Прогноз: погашение старой КЗ | B31: 0 | C31: Сумма, планируемая в первом месяце прогноза
A32: Начальный капитал | B32: 0 | C32: Вводится независимо от активов, не балансирующая формула
A33: Начальный кредит | B33: 0 | C33: Остаток на начало учёта; график только нового кредита
A34: Начальные налоги | B34: 0 | C34: Сальдо обязательств на начало учёта
A35: Начальная прибыль | B35: 0 | C35: Накопленный результат до начала книги
A36: Начальная ДЗ | B36: 0 | C36: Для детализации начальной ДЗ нужны документы переноса
A37: Начальная КЗ | B37: 0 | C37: Для детализации начальной КЗ нужны документы переноса
A38: Начальные прочие активы | B38: 0 | C38: Запасы и прочие активы: без автоматического движения
A39: Начальные прочие обязательства | B39: 0 | C39: Без автоматического движения
A40: Ручной налог на результат | B40: 0 | C40: Для неподдерживаемых режимов: задаётся по месяцам в НАЛОГИ

Sheet ДДС
A1: Главная панель | D1: Настройки | F1: Контроль
A2: ДДС
A3: LEO STUDIO • Управленческий учёт • RUB
A6: Показатель | B6: =DATE(Год,1,1) -> 46023 | C6: =DATE(Год,2,1) -> 46054 | D6: =DATE(Год,3,1) -> 46082 | E6: =DATE(Год,4,1) -> 46113 | F6: =DATE(Год,5,1) -> 46143 | G6: =DATE(Год,6,1) -> 46174 | H6: =DATE(Год,7,1) -> 46204 | I6: =DATE(Год,8,1) -> 46235 | J6: =DATE(Год,9,1) -> 46266 | K6: =DATE(Год,10,1) -> 46296 | L6: =DATE(Год,11,1) -> 46327 | M6: =DATE(Год,12,1) -> 46357 | N6: Год / итог
A7: Начальный остаток | B7: =SUM(Accounts[Начальный]) -> 0 | C7: =B14 -> 645622.77 | D7: =C14 -> 508045.54 | E7: =D14 -> 566868.31 | F7: =E14 -> 635891.08 | G7: =F14 -> 770313.85 | H7: =G14 -> 881936.62 | I7: =H14 -> 978159.39 | J7: =I14 -> 795982.16 | ... M7: =L14 -> 1387650.5 | N7: =B7 -> 0
A8: Операционные поступления | B8: =SUMIFS(Cash[Поток],Cash[Дата],"<="&ДатаОтчета,Cash[Статус],"Проведён",Cash[Дата],">="&B$6,Cash[Дата],"<"&EDATE(B$6,1),Cash[Класс ДДС],"Операционный",Cash[Поток],">0") -> 420000 | C8: =SUMIFS(Cash[Поток],Cash[Дата],"<="&ДатаОтчета,Cash[Статус],"Проведён",Cash[Дата],">="&C$6,Cash[Дата],"<"&EDATE(C$6,1),Cash[Класс ДДС],"Операционный",Cash[Поток],">0") -> 180000 | D8: =SUMIFS(Cash[Поток],Cash[Дата],"<="&ДатаОтчета,Cash[Статус],"Проведён",Cash[Дата],">="&D$6,Cash[Дата],"<"&EDATE(D$6,1),Cash[Класс ДДС],"Операционный",Cash[Поток],">0") -> 510000 | E8: =SUMIFS(Cash[Поток],Cash[Дата],"<="&ДатаОтчета,Cash[Статус],"Проведён",Cash[Дата],">="&E$6,Cash[Дата],"<"&EDATE(E$6,1),Cash[Класс ДДС],"Операционный",Cash[Поток],">0") -> 550000 | F8: =SUMIFS(Cash[Поток],Cash[Дата],"<="&ДатаОтчета,Cash[Статус],"Проведён",Cash[Дата],">="&F$6,Cash[Дата],"<"&EDATE(F$6,1),Cash[Класс ДДС],"Операционный",Cash[Поток],">0") -> 580000 | G8: =SUMIFS(Cash[Поток],Cash[Дата],"<="&ДатаОтчета,Cash[Статус],"Проведён",Cash[Дата],">="&G$6,Cash[Дата],"<"&EDATE(G$6,1),Cash[Класс ДДС],"Операционный",Cash[Поток],">0") -> 620000 | H8: =SUMIFS(Cash[Поток],Cash[Дата],"<="&ДатаОтчета,Cash[Статус],"Проведён",Cash[Дата],">="&H$6,Cash[Дата],"<"&EDATE(H$6,1),Cash[Класс ДДС],"Операционный",Cash[Поток],">0") -> 590000 | I8: =SUMIFS(Cash[Поток],Cash[Дата],"<="&ДатаОтчета,Cash[Статус],"Проведён",Cash[Дата],">="&I$6,Cash[Дата],"<"&EDATE(I$6,1),Cash[Класс ДДС],"Операционный",Cash[Поток],">0") -> 210000 | ... M8: =SUMIFS(Cash[Поток],Cash[Дата],"<="&ДатаОтчета,Cash[Статус],"Проведён",Cash[Дата],">="&M$6,Cash[Дата],"<"&EDATE(M$6,1),Cash[Класс ДДС],"Операционный",Cash[Поток],">0") -> 760960 | N8: =SUM(B8:M8) -> 6540960
A9: Операционные выплаты | B9: =-SUMIFS(Cash[Поток],Cash[Дата],"<="&ДатаОтчета,Cash[Статус],"Проведён",Cash[Дата],">="&B$6,Cash[Дата],"<"&EDATE(B$6,1),Cash[Класс ДДС],"Операционный",Cash[Поток],"<0") -> 383900 | C9: =-SUMIFS(Cash[Поток],Cash[Дата],"<="&ДатаОтчета,Cash[Статус],"Проведён",Cash[Дата],">="&C$6,Cash[Дата],"<"&EDATE(C$6,1),Cash[Класс ДДС],"Операционный",Cash[Поток],"<0") -> 306942.84 | D9: =-SUMIFS(Cash[Поток],Cash[Дата],"<="&ДатаОтчета,Cash[Статус],"Проведён",Cash[Дата],">="&D$6,Cash[Дата],"<"&EDATE(D$6,1),Cash[Класс ДДС],"Операционный",Cash[Поток],"<0") -> 415383.33 | E9: =-SUMIFS(Cash[Поток],Cash[Дата],"<="&ДатаОтчета,Cash[Статус],"Проведён",Cash[Дата],">="&E$6,Cash[Дата],"<"&EDATE(E$6,1),Cash[Класс ДДС],"Операционный",Cash[Поток],"<0") -> 470021.42 | F9: =-SUMIFS(Cash[Поток],Cash[Дата],"<="&ДатаОтчета,Cash[Статус],"Проведён",Cash[Дата],">="&F$6,Cash[Дата],"<"&EDATE(F$6,1),Cash[Класс ДДС],"Операционный",Cash[Поток],"<0") -> 434457.08 | G9: =-SUMIFS(Cash[Поток],Cash[Дата],"<="&ДатаОтчета,Cash[Статус],"Проведён",Cash[Дата],">="&G$6,Cash[Дата],"<"&EDATE(G$6,1),Cash[Класс ДДС],"Операционный",Cash[Поток],"<0") -> 447090.28 | H9: =-SUMIFS(Cash[Поток],Cash[Дата],"<="&ДатаОтчета,Cash[Статус],"Проведён",Cash[Дата],">="&H$6,Cash[Дата],"<"&EDATE(H$6,1),Cash[Класс ДДС],"Операционный",Cash[Поток],"<0") -> 481945.97 | I9: =-SUMIFS(Cash[Поток],Cash[Дата],"<="&ДатаОтчета,Cash[Статус],"Проведён",Cash[Дата],">="&I$6,Cash[Дата],"<"&EDATE(I$6,1),Cash[Класс ДДС],"Операционный",Cash[Поток],"<0") -> 380168.5 | ... M9: =-SUMIFS(Cash[Поток],Cash[Дата],"<="&ДатаОтчета,Cash[Статус],"Проведён",Cash[Дата],">="&M$6,Cash[Дата],"<"&EDATE(M$6,1),Cash[Класс ДДС],"Операционный",Cash[Поток],"<0") -> 435821.61 | N9: =SUM(B9:M9) -> 5221944.9
A10: Операционный поток | B10: =B8-B9 -> 36100 | C10: =C8-C9 -> -126942.84 | D10: =D8-D9 -> 94616.67 | E10: =E8-E9 -> 79978.58 | F10: =F8-F9 -> 145542.92 | G10: =G8-G9 -> 172909.72 | H10: =H8-H9 -> 108054.03 | I10: =I8-I9 -> -170168.5 | ... M10: =M8-M9 -> 325138.39 | N10: =SUM(B10:M10) -> 1319015.1
A11: Инвестиционный поток | B11: =SUMIFS(Cash[Поток],Cash[Дата],"<="&ДатаОтчета,Cash[Статус],"Проведён",Cash[Дата],">="&B$6,Cash[Дата],"<"&EDATE(B$6,1),Cash[Класс ДДС],"Инвестиционный") -> -180000 | C11: =SUMIFS(Cash[Поток],Cash[Дата],"<="&ДатаОтчета,Cash[Статус],"Проведён",Cash[Дата],">="&C$6,Cash[Дата],"<"&EDATE(C$6,1),Cash[Класс ДДС],"Инвестиционный") -> 0 | D11: =SUMIFS(Cash[Поток],Cash[Дата],"<="&ДатаОтчета,Cash[Статус],"Проведён",Cash[Дата],">="&D$6,Cash[Дата],"<"&EDATE(D$6,1),Cash[Класс ДДС],"Инвестиционный") -> 0 | E11: =SUMIFS(Cash[Поток],Cash[Дата],"<="&ДатаОтчета,Cash[Статус],"Проведён",Cash[Дата],">="&E$6,Cash[Дата],"<"&EDATE(E$6,1),Cash[Класс ДДС],"Инвестиционный") -> 0 | F11: =SUMIFS(Cash[Поток],Cash[Дата],"<="&ДатаОтчета,Cash[Статус],"Проведён",Cash[Дата],">="&F$6,Cash[Дата],"<"&EDATE(F$6,1),Cash[Класс ДДС],"Инвестиционный") -> 0 | G11: =SUMIFS(Cash[Поток],Cash[Дата],"<="&ДатаОтчета,Cash[Статус],"Проведён",Cash[Дата],">="&G$6,Cash[Дата],"<"&EDATE(G$6,1),Cash[Класс ДДС],"Инвестиционный") -> 0 | H11: =SUMIFS(Cash[Поток],Cash[Дата],"<="&ДатаОтчета,Cash[Статус],"Проведён",Cash[Дата],">="&H$6,Cash[Дата],"<"&EDATE(H$6,1),Cash[Класс ДДС],"Инвестиционный") -> 0 | I11: =SUMIFS(Cash[Поток],Cash[Дата],"<="&ДатаОтчета,Cash[Статус],"Проведён",Cash[Дата],">="&I$6,Cash[Дата],"<"&EDATE(I$6,1),Cash[Класс ДДС],"Инвестиционный") -> 0 | ... M11: =SUMIFS(Cash[Поток],Cash[Дата],"<="&ДатаОтчета,Cash[Статус],"Проведён",Cash[Дата],">="&M$6,Cash[Дата],"<"&EDATE(M$6,1),Cash[Класс ДДС],"Инвестиционный") -> 0 | N11: =SUM(B11:M11) -> -180000
A12: Финансовый поток | B12: =SUMIFS(Cash[Поток],Cash[Дата],"<="&ДатаОтчета,Cash[Статус],"Проведён",Cash[Дата],">="&B$6,Cash[Дата],"<"&EDATE(B$6,1),Cash[Класс ДДС],"Финансовый") -> 789522.77 | C12: =SUMIFS(Cash[Поток],Cash[Дата],"<="&ДатаОтчета,Cash[Статус],"Проведён",Cash[Дата],">="&C$6,Cash[Дата],"<"&EDATE(C$6,1),Cash[Класс ДДС],"Финансовый") -> -10634.39 | D12: =SUMIFS(Cash[Поток],Cash[Дата],"<="&ДатаОтчета,Cash[Статус],"Проведён",Cash[Дата],">="&D$6,Cash[Дата],"<"&EDATE(D$6,1),Cash[Класс ДДС],"Финансовый") -> -35793.9 | E12: =SUMIFS(Cash[Поток],Cash[Дата],"<="&ДатаОтчета,Cash[Статус],"Проведён",Cash[Дата],">="&E$6,Cash[Дата],"<"&EDATE(E$6,1),Cash[Класс ДДС],"Финансовый") -> -10955.81 | F12: =SUMIFS(Cash[Поток],Cash[Дата],"<="&ДатаОтчета,Cash[Статус],"Проведён",Cash[Дата],">="&F$6,Cash[Дата],"<"&EDATE(F$6,1),Cash[Класс ДДС],"Финансовый") -> -11120.15 | G12: =SUMIFS(Cash[Поток],Cash[Дата],"<="&ДатаОтчета,Cash[Статус],"Проведён",Cash[Дата],">="&G$6,Cash[Дата],"<"&EDATE(G$6,1),Cash[Класс ДДС],"Финансовый") -> -61286.95 | H12: =SUMIFS(Cash[Поток],Cash[Дата],"<="&ДатаОтчета,Cash[Статус],"Проведён",Cash[Дата],">="&H$6,Cash[Дата],"<"&EDATE(H$6,1),Cash[Класс ДДС],"Финансовый") -> -11831.26 | I12: =SUMIFS(Cash[Поток],Cash[Дата],"<="&ДатаОтчета,Cash[Статус],"Проведён",Cash[Дата],">="&I$6,Cash[Дата],"<"&EDATE(I$6,1),Cash[Класс ДДС],"Финансовый") -> -12008.73 | ... M12: =SUMIFS(Cash[Поток],Cash[Дата],"<="&ДатаОтчета,Cash[Статус],"Проведён",Cash[Дата],">="&M$6,Cash[Дата],"<"&EDATE(M$6,1),Cash[Класс ДДС],"Финансовый") -> -37745.62 | N12: =SUM(B12:M12) -> 536028.15
A13: Чистый денежный поток | B13: =SUM(B10:B12) -> 645622.77 | C13: =SUM(C10:C12) -> -137577.23 | D13: =SUM(D10:D12) -> 58822.77 | E13: =SUM(E10:E12) -> 69022.77 | F13: =SUM(F10:F12) -> 134422.77 | G13: =SUM(G10:G12) -> 111622.77 | H13: =SUM(H10:H12) -> 96222.77 | I13: =SUM(I10:I12) -> -182177.23 | ... M13: =SUM(M10:M12) -> 287392.77 | N13: =SUM(B13:M13) -> 1675043.2
A14: Конечный остаток | B14: =B7+B13 -> 645622.77 | C14: =C7+C13 -> 508045.54 | D14: =D7+D13 -> 566868.31 | E14: =E7+E13 -> 635891.08 | F14: =F7+F13 -> 770313.85 | G14: =G7+G13 -> 881936.62 | H14: =H7+H13 -> 978159.39 | I14: =I7+I13 -> 795982.16 | ... M14: =M7+M13 -> 1675043.2 | N14: =M14 -> 1675043.2
A16: Поступления всего | B16: =SUMIFS(Cash[Поток],Cash[Дата],"<="&ДатаОтчета,Cash[Статус],"Проведён",Cash[Дата],">="&B$6,Cash[Дата],"<"&EDATE(B$6,1),Cash[Класс ДДС],"<>Внутренний",Cash[Поток],">0") -> 1220000 | C16: =SUMIFS(Cash[Поток],Cash[Дата],"<="&ДатаОтчета,Cash[Статус],"Проведён",Cash[Дата],">="&C$6,Cash[Дата],"<"&EDATE(C$6,1),Cash[Класс ДДС],"<>Внутренний",Cash[Поток],">0") -> 180000 | D16: =SUMIFS(Cash[Поток],Cash[Дата],"<="&ДатаОтчета,Cash[Статус],"Проведён",Cash[Дата],">="&D$6,Cash[Дата],"<"&EDATE(D$6,1),Cash[Класс ДДС],"<>Внутренний",Cash[Поток],">0") -> 510000 | E16: =SUMIFS(Cash[Поток],Cash[Дата],"<="&ДатаОтчета,Cash[Статус],"Проведён",Cash[Дата],">="&E$6,Cash[Дата],"<"&EDATE(E$6,1),Cash[Класс ДДС],"<>Внутренний",Cash[Поток],">0") -> 550000 | F16: =SUMIFS(Cash[Поток],Cash[Дата],"<="&ДатаОтчета,Cash[Статус],"Проведён",Cash[Дата],">="&F$6,Cash[Дата],"<"&EDATE(F$6,1),Cash[Класс ДДС],"<>Внутренний",Cash[Поток],">0") -> 580000 | G16: =SUMIFS(Cash[Поток],Cash[Дата],"<="&ДатаОтчета,Cash[Статус],"Проведён",Cash[Дата],">="&G$6,Cash[Дата],"<"&EDATE(G$6,1),Cash[Класс ДДС],"<>Внутренний",Cash[Поток],">0") -> 620000 | H16: =SUMIFS(Cash[Поток],Cash[Дата],"<="&ДатаОтчета,Cash[Статус],"Проведён",Cash[Дата],">="&H$6,Cash[Дата],"<"&EDATE(H$6,1),Cash[Класс ДДС],"<>Внутренний",Cash[Поток],">0") -> 590000 | I16: =SUMIFS(Cash[Поток],Cash[Дата],"<="&ДатаОтчета,Cash[Статус],"Проведён",Cash[Дата],">="&I$6,Cash[Дата],"<"&EDATE(I$6,1),Cash[Класс ДДС],"<>Внутренний",Cash[Поток],">0") -> 210000 | ... M16: =SUMIFS(Cash[Поток],Cash[Дата],"<="&ДатаОтчета,Cash[Статус],"Проведён",Cash[Дата],">="&M$6,Cash[Дата],"<"&EDATE(M$6,1),Cash[Класс ДДС],"<>Внутренний",Cash[Поток],">0") -> 760960 | N16: =SUM(B16:M16) -> 7340960
A17: Выплаты всего | B17: =-SUMIFS(Cash[Поток],Cash[Дата],"<="&ДатаОтчета,Cash[Статус],"Проведён",Cash[Дата],">="&B$6,Cash[Дата],"<"&EDATE(B$6,1),Cash[Класс ДДС],"<>Внутренний",Cash[Поток],"<0") -> 574377.23 | C17: =-SUMIFS(Cash[Поток],Cash[Дата],"<="&ДатаОтчета,Cash[Статус],"Проведён",Cash[Дата],">="&C$6,Cash[Дата],"<"&EDATE(C$6,1),Cash[Класс ДДС],"<>Внутренний",Cash[Поток],"<0") -> 317577.23 | D17: =-SUMIFS(Cash[Поток],Cash[Дата],"<="&ДатаОтчета,Cash[Статус],"Проведён",Cash[Дата],">="&D$6,Cash[Дата],"<"&EDATE(D$6,1),Cash[Класс ДДС],"<>Внутренний",Cash[Поток],"<0") -> 451177.23 | E17: =-SUMIFS(Cash[Поток],Cash[Дата],"<="&ДатаОтчета,Cash[Статус],"Проведён",Cash[Дата],">="&E$6,Cash[Дата],"<"&EDATE(E$6,1),Cash[Класс ДДС],"<>Внутренний",Cash[Поток],"<0") -> 480977.23 | F17: =-SUMIFS(Cash[Поток],Cash[Дата],"<="&ДатаОтчета,Cash[Статус],"Проведён",Cash[Дата],">="&F$6,Cash[Дата],"<"&EDATE(F$6,1),Cash[Класс ДДС],"<>Внутренний",Cash[Поток],"<0") -> 445577.23 | G17: =-SUMIFS(Cash[Поток],Cash[Дата],"<="&ДатаОтчета,Cash[Статус],"Проведён",Cash[Дата],">="&G$6,Cash[Дата],"<"&EDATE(G$6,1),Cash[Класс ДДС],"<>Внутренний",Cash[Поток],"<0") -> 508377.23 | H17: =-SUMIFS(Cash[Поток],Cash[Дата],"<="&ДатаОтчета,Cash[Статус],"Проведён",Cash[Дата],">="&H$6,Cash[Дата],"<"&EDATE(H$6,1),Cash[Класс ДДС],"<>Внутренний",Cash[Поток],"<0") -> 493777.23 | I17: =-SUMIFS(Cash[Поток],Cash[Дата],"<="&ДатаОтчета,Cash[Статус],"Проведён",Cash[Дата],">="&I$6,Cash[Дата],"<"&EDATE(I$6,1),Cash[Класс ДДС],"<>Внутренний",Cash[Поток],"<0") -> 392177.23 | ... M17: =-SUMIFS(Cash[Поток],Cash[Дата],"<="&ДатаОтчета,Cash[Статус],"Проведён",Cash[Дата],">="&M$6,Cash[Дата],"<"&EDATE(M$6,1),Cash[Класс ДДС],"<>Внутренний",Cash[Поток],"<0") -> 473567.23 | N17: =SUM(B17:M17) -> 5665916.8
A18: Переводы внутри компании | B18: =SUMIFS(Cash[Сумма],Cash[Дата],"<="&ДатаОтчета,Cash[Статус],"Проведён",Cash[Тип],"Перевод",Cash[Дата],">="&B$6,Cash[Дата],"<"&EDATE(B$6,1)) -> 15000 | C18: =SUMIFS(Cash[Сумма],Cash[Дата],"<="&ДатаОтчета,Cash[Статус],"Проведён",Cash[Тип],"Перевод",Cash[Дата],">="&C$6,Cash[Дата],"<"&EDATE(C$6,1)) -> 15000 | D18: =SUMIFS(Cash[Сумма],Cash[Дата],"<="&ДатаОтчета,Cash[Статус],"Проведён",Cash[Тип],"Перевод",Cash[Дата],">="&D$6,Cash[Дата],"<"&EDATE(D$6,1)) -> 15000 | E18: =SUMIFS(Cash[Сумма],Cash[Дата],"<="&ДатаОтчета,Cash[Статус],"Проведён",Cash[Тип],"Перевод",Cash[Дата],">="&E$6,Cash[Дата],"<"&EDATE(E$6,1)) -> 15000 | F18: =SUMIFS(Cash[Сумма],Cash[Дата],"<="&ДатаОтчета,Cash[Статус],"Проведён",Cash[Тип],"Перевод",Cash[Дата],">="&F$6,Cash[Дата],"<"&EDATE(F$6,1)) -> 15000 | G18: =SUMIFS(Cash[Сумма],Cash[Дата],"<="&ДатаОтчета,Cash[Статус],"Проведён",Cash[Тип],"Перевод",Cash[Дата],">="&G$6,Cash[Дата],"<"&EDATE(G$6,1)) -> 15000 | H18: =SUMIFS(Cash[Сумма],Cash[Дата],"<="&ДатаОтчета,Cash[Статус],"Проведён",Cash[Тип],"Перевод",Cash[Дата],">="&H$6,Cash[Дата],"<"&EDATE(H$6,1)) -> 15000 | I18: =SUMIFS(Cash[Сумма],Cash[Дата],"<="&ДатаОтчета,Cash[Статус],"Проведён",Cash[Тип],"Перевод",Cash[Дата],">="&I$6,Cash[Дата],"<"&EDATE(I$6,1)) -> 15000 | ... M18: =SUMIFS(Cash[Сумма],Cash[Дата],"<="&ДатаОтчета,Cash[Статус],"Проведён",Cash[Тип],"Перевод",Cash[Дата],">="&M$6,Cash[Дата],"<"&EDATE(M$6,1)) -> 15000 | N18: =SUM(B18:M18) -> 180000

Sheet ОПиУ
A1: Главная панель | D1: Настройки | F1: Контроль
A2: ОПиУ
A3: LEO STUDIO • Управленческий учёт • RUB
A6: Показатель | B6: =DATE(Год,1,1) -> 46023 | C6: =DATE(Год,2,1) -> 46054 | D6: =DATE(Год,3,1) -> 46082 | E6: =DATE(Год,4,1) -> 46113 | F6: =DATE(Год,5,1) -> 46143 | G6: =DATE(Год,6,1) -> 46174 | H6: =DATE(Год,7,1) -> 46204 | I6: =DATE(Год,8,1) -> 46235 | J6: =DATE(Год,9,1) -> 46266 | K6: =DATE(Год,10,1) -> 46296 | L6: =DATE(Год,11,1) -> 46327 | M6: =DATE(Год,12,1) -> 46357 | N6: Год / итог
A7: Выручка | B7: =SUMIFS(Docs[Сумма],Docs[Дата],"<="&ДатаОтчета,Docs[Статус],"Проведён",Docs[Вид],"Выручка",Docs[Дата],">="&B$6,Docs[Дата],"<"&EDATE(B$6,1)) -> 420000 | C7: =SUMIFS(Docs[Сумма],Docs[Дата],"<="&ДатаОтчета,Docs[Статус],"Проведён",Docs[Вид],"Выручка",Docs[Дата],">="&C$6,Docs[Дата],"<"&EDATE(C$6,1)) -> 180000 | D7: =SUMIFS(Docs[Сумма],Docs[Дата],"<="&ДатаОтчета,Docs[Статус],"Проведён",Docs[Вид],"Выручка",Docs[Дата],">="&D$6,Docs[Дата],"<"&EDATE(D$6,1)) -> 507000 | E7: =SUMIFS(Docs[Сумма],Docs[Дата],"<="&ДатаОтчета,Docs[Статус],"Проведён",Docs[Вид],"Выручка",Docs[Дата],">="&E$6,Docs[Дата],"<"&EDATE(E$6,1)) -> 550000 | F7: =SUMIFS(Docs[Сумма],Docs[Дата],"<="&ДатаОтчета,Docs[Статус],"Проведён",Docs[Вид],"Выручка",Docs[Дата],">="&F$6,Docs[Дата],"<"&EDATE(F$6,1)) -> 580000 | G7: =SUMIFS(Docs[Сумма],Docs[Дата],"<="&ДатаОтчета,Docs[Статус],"Проведён",Docs[Вид],"Выручка",Docs[Дата],">="&G$6,Docs[Дата],"<"&EDATE(G$6,1)) -> 620000 | H7: =SUMIFS(Docs[Сумма],Docs[Дата],"<="&ДатаОтчета,Docs[Статус],"Проведён",Docs[Вид],"Выручка",Docs[Дата],">="&H$6,Docs[Дата],"<"&EDATE(H$6,1)) -> 590000 | I7: =SUMIFS(Docs[Сумма],Docs[Дата],"<="&ДатаОтчета,Docs[Статус],"Проведён",Docs[Вид],"Выручка",Docs[Дата],">="&I$6,Docs[Дата],"<"&EDATE(I$6,1)) -> 210000 | ... M7: =SUMIFS(Docs[Сумма],Docs[Дата],"<="&ДатаОтчета,Docs[Статус],"Проведён",Docs[Вид],"Выручка",Docs[Дата],">="&M$6,Docs[Дата],"<"&EDATE(M$6,1)) -> 820000 | N7: =SUM(B7:M7) -> 6597000
A8: Себестоимость | B8: =SUMIFS(Docs[Сумма],Docs[Дата],"<="&ДатаОтчета,Docs[Статус],"Проведён",Docs[Вид],"Себестоимость",Docs[Дата],">="&B$6,Docs[Дата],"<"&EDATE(B$6,1)) -> 134400 | C8: =SUMIFS(Docs[Сумма],Docs[Дата],"<="&ДатаОтчета,Docs[Статус],"Проведён",Docs[Вид],"Себестоимость",Docs[Дата],">="&C$6,Docs[Дата],"<"&EDATE(C$6,1)) -> 57600 | D8: =SUMIFS(Docs[Сумма],Docs[Дата],"<="&ДатаОтчета,Docs[Статус],"Проведён",Docs[Вид],"Себестоимость",Docs[Дата],">="&D$6,Docs[Дата],"<"&EDATE(D$6,1)) -> 163200 | E8: =SUMIFS(Docs[Сумма],Docs[Дата],"<="&ДатаОтчета,Docs[Статус],"Проведён",Docs[Вид],"Себестоимость",Docs[Дата],">="&E$6,Docs[Дата],"<"&EDATE(E$6,1)) -> 176000 | F8: =SUMIFS(Docs[Сумма],Docs[Дата],"<="&ДатаОтчета,Docs[Статус],"Проведён",Docs[Вид],"Себестоимость",Docs[Дата],">="&F$6,Docs[Дата],"<"&EDATE(F$6,1)) -> 185600 | G8: =SUMIFS(Docs[Сумма],Docs[Дата],"<="&ДатаОтчета,Docs[Статус],"Проведён",Docs[Вид],"Себестоимость",Docs[Дата],">="&G$6,Docs[Дата],"<"&EDATE(G$6,1)) -> 198400 | H8: =SUMIFS(Docs[Сумма],Docs[Дата],"<="&ДатаОтчета,Docs[Статус],"Проведён",Docs[Вид],"Себестоимость",Docs[Дата],">="&H$6,Docs[Дата],"<"&EDATE(H$6,1)) -> 188800 | I8: =SUMIFS(Docs[Сумма],Docs[Дата],"<="&ДатаОтчета,Docs[Статус],"Проведён",Docs[Вид],"Себестоимость",Docs[Дата],">="&I$6,Docs[Дата],"<"&EDATE(I$6,1)) -> 67200 | ... M8: =SUMIFS(Docs[Сумма],Docs[Дата],"<="&ДатаОтчета,Docs[Статус],"Проведён",Docs[Вид],"Себестоимость",Docs[Дата],">="&M$6,Docs[Дата],"<"&EDATE(M$6,1)) -> 262400 | N8: =SUM(B8:M8) -> 2112000
A9: Валовая прибыль | B9: =B7-B8 -> 285600 | C9: =C7-C8 -> 122400 | D9: =D7-D8 -> 343800 | E9: =E7-E8 -> 374000 | F9: =F7-F8 -> 394400 | G9: =G7-G8 -> 421600 | H9: =H7-H8 -> 401200 | I9: =I7-I8 -> 142800 | ... M9: =M7-M8 -> 557600 | N9: =SUM(B9:M9) -> 4485000
A10: Операционные расходы | B10: =SUMIFS(Docs[Сумма],Docs[Дата],"<="&ДатаОтчета,Docs[Статус],"Проведён",Docs[Вид],"Операционные",Docs[Дата],">="&B$6,Docs[Дата],"<"&EDATE(B$6,1)) -> 245000 | C10: =SUMIFS(Docs[Сумма],Docs[Дата],"<="&ДатаОтчета,Docs[Статус],"Проведён",Docs[Вид],"Операционные",Docs[Дата],">="&C$6,Docs[Дата],"<"&EDATE(C$6,1)) -> 245000 | D10: =SUMIFS(Docs[Сумма],Docs[Дата],"<="&ДатаОтчета,Docs[Статус],"Проведён",Docs[Вид],"Операционные",Docs[Дата],">="&D$6,Docs[Дата],"<"&EDATE(D$6,1)) -> 245000 | E10: =SUMIFS(Docs[Сумма],Docs[Дата],"<="&ДатаОтчета,Docs[Статус],"Проведён",Docs[Вид],"Операционные",Docs[Дата],">="&E$6,Docs[Дата],"<"&EDATE(E$6,1)) -> 245000 | F10: =SUMIFS(Docs[Сумма],Docs[Дата],"<="&ДатаОтчета,Docs[Статус],"Проведён",Docs[Вид],"Операционные",Docs[Дата],">="&F$6,Docs[Дата],"<"&EDATE(F$6,1)) -> 245000 | G10: =SUMIFS(Docs[Сумма],Docs[Дата],"<="&ДатаОтчета,Docs[Статус],"Проведён",Docs[Вид],"Операционные",Docs[Дата],">="&G$6,Docs[Дата],"<"&EDATE(G$6,1)) -> 245000 | H10: =SUMIFS(Docs[Сумма],Docs[Дата],"<="&ДатаОтчета,Docs[Статус],"Проведён",Docs[Вид],"Операционные",Docs[Дата],">="&H$6,Docs[Дата],"<"&EDATE(H$6,1)) -> 245000 | I10: =SUMIFS(Docs[Сумма],Docs[Дата],"<="&ДатаОтчета,Docs[Статус],"Проведён",Docs[Вид],"Операционные",Docs[Дата],">="&I$6,Docs[Дата],"<"&EDATE(I$6,1)) -> 310000 | ... M10: =SUMIFS(Docs[Сумма],Docs[Дата],"<="&ДатаОтчета,Docs[Статус],"Проведён",Docs[Вид],"Операционные",Docs[Дата],">="&M$6,Docs[Дата],"<"&EDATE(M$6,1)) -> 245000 | N10: =SUM(B10:M10) -> 3005000
A11: Амортизация | B11: =SUM(АКТИВЫ!K7:K56) -> 0 | C11: =SUM(АКТИВЫ!L7:L56) -> 5000 | D11: =SUM(АКТИВЫ!M7:M56) -> 5000 | E11: =SUM(АКТИВЫ!N7:N56) -> 5000 | F11: =SUM(АКТИВЫ!O7:O56) -> 5000 | G11: =SUM(АКТИВЫ!P7:P56) -> 5000 | H11: =SUM(АКТИВЫ!Q7:Q56) -> 5000 | I11: =SUM(АКТИВЫ!R7:R56) -> 5000 | ... M11: =SUM(АКТИВЫ!V7:V56) -> 5000 | N11: =SUM(B11:M11) -> 55000
A12: Операционная прибыль | B12: =B9-B10-B11 -> 40600 | C12: =C9-C10-C11 -> -127600 | D12: =D9-D10-D11 -> 93800 | E12: =E9-E10-E11 -> 124000 | F12: =F9-F10-F11 -> 144400 | G12: =G9-G10-G11 -> 171600 | H12: =H9-H10-H11 -> 151200 | I12: =I9-I10-I11 -> -172200 | ... M12: =M9-M10-M11 -> 307600 | N12: =SUM(B12:M12) -> 1425000
A13: Проценты | B13: =SUMIFS(Docs[Сумма],Docs[Дата],"<="&ДатаОтчета,Docs[Статус],"Проведён",Docs[Вид],"Проценты",Docs[Дата],">="&B$6,Docs[Дата],"<"&EDATE(B$6,1)) -> 4500 | C13: =SUMIFS(Docs[Сумма],Docs[Дата],"<="&ДатаОтчета,Docs[Статус],"Проведён",Docs[Вид],"Проценты",Docs[Дата],">="&C$6,Docs[Дата],"<"&EDATE(C$6,1)) -> 4342.84 | D13: =SUMIFS(Docs[Сумма],Docs[Дата],"<="&ДатаОтчета,Docs[Статус],"Проведён",Docs[Вид],"Проценты",Docs[Дата],">="&D$6,Docs[Дата],"<"&EDATE(D$6,1)) -> 4183.33 | E13: =SUMIFS(Docs[Сумма],Docs[Дата],"<="&ДатаОтчета,Docs[Статус],"Проведён",Docs[Вид],"Проценты",Docs[Дата],">="&E$6,Docs[Дата],"<"&EDATE(E$6,1)) -> 4021.42 | F13: =SUMIFS(Docs[Сумма],Docs[Дата],"<="&ДатаОтчета,Docs[Статус],"Проведён",Docs[Вид],"Проценты",Docs[Дата],">="&F$6,Docs[Дата],"<"&EDATE(F$6,1)) -> 3857.08 | G13: =SUMIFS(Docs[Сумма],Docs[Дата],"<="&ДатаОтчета,Docs[Статус],"Проведён",Docs[Вид],"Проценты",Docs[Дата],">="&G$6,Docs[Дата],"<"&EDATE(G$6,1)) -> 3690.28 | H13: =SUMIFS(Docs[Сумма],Docs[Дата],"<="&ДатаОтчета,Docs[Статус],"Проведён",Docs[Вид],"Проценты",Docs[Дата],">="&H$6,Docs[Дата],"<"&EDATE(H$6,1)) -> 3145.97 | I13: =SUMIFS(Docs[Сумма],Docs[Дата],"<="&ДатаОтчета,Docs[Статус],"Проведён",Docs[Вид],"Проценты",Docs[Дата],">="&I$6,Docs[Дата],"<"&EDATE(I$6,1)) -> 2968.5 | ... M13: =SUMIFS(Docs[Сумма],Docs[Дата],"<="&ДатаОтчета,Docs[Статус],"Проведён",Docs[Вид],"Проценты",Docs[Дата],">="&M$6,Docs[Дата],"<"&EDATE(M$6,1)) -> 2231.61 | N13: =SUM(B13:M13) -> 40754.91
A14: Налог на результат | B14: =НАЛОГИ!H7 -> 25200 | C14: =НАЛОГИ!H8 -> 10800 | D14: =НАЛОГИ!H9 -> 30420 | E14: =НАЛОГИ!H10 -> 33000 | F14: =НАЛОГИ!H11 -> 34800 | G14: =НАЛОГИ!H12 -> 37200 | H14: =НАЛОГИ!H13 -> 35400 | I14: =НАЛОГИ!H14 -> 12600 | J14: =НАЛОГИ!H15 -> 39000 | K14: =НАЛОГИ!H16 -> 42600 | L14: =НАЛОГИ!H17 -> 45600 | M14: =НАЛОГИ!H18 -> 45657.6 | N14: =SUM(B14:M14) -> 392277.6
A15: Взносы ИП за себя | B15: =НАЛОГИ!L7 -> 5982.5 | C15: =НАЛОГИ!L8 -> 6582.5 | D15: =НАЛОГИ!L9 -> 9852.5 | E15: =НАЛОГИ!L10 -> 10282.5 | F15: =НАЛОГИ!L11 -> 10582.5 | G15: =НАЛОГИ!L12 -> 10982.5 | H15: =НАЛОГИ!L13 -> 10682.5 | I15: =НАЛОГИ!L14 -> 6882.5 | J15: =НАЛОГИ!L15 -> 11282.5 | K15: =НАЛОГИ!L16 -> 11882.5 | L15: =НАЛОГИ!L17 -> 12382.5 | M15: =НАЛОГИ!L18 -> 12392.1 | N15: =SUM(B15:M15) -> 119769.6
A16: Итоговый результат | B16: =B12-SUM(B13:B15) -> 4917.5 | C16: =C12-SUM(C13:C15) -> -149325.34 | D16: =D12-SUM(D13:D15) -> 49344.17 | E16: =E12-SUM(E13:E15) -> 76696.08 | F16: =F12-SUM(F13:F15) -> 95160.42 | G16: =G12-SUM(G13:G15) -> 119727.22 | H16: =H12-SUM(H13:H15) -> 101971.53 | I16: =I12-SUM(I13:I15) -> -194651 | ... M16: =M12-SUM(M13:M15) -> 247318.69 | N16: =SUM(B16:M16) -> 872197.89
A17: Итоговая рентабельность | B17: =IF(B7=0,"н/д",B16/B7) -> 0.011708333 | C17: =IF(C7=0,"н/д",C16/C7) -> -0.82958522 | D17: =IF(D7=0,"н/д",D16/D7) -> 0.097325779 | E17: =IF(E7=0,"н/д",E16/E7) -> 0.13944742 | F17: =IF(F7=0,"н/д",F16/F7) -> 0.16406969 | G17: =IF(G7=0,"н/д",G16/G7) -> 0.19310842 | H17: =IF(H7=0,"н/д",H16/H7) -> 0.1728331 | I17: =IF(I7=0,"н/д",I16/I7) -> -0.92690952 | ... N17: =IF(N7=0,"н/д",N16/N7) -> 0.13221129
A18: Убыточный месяц | B18: =IF(B16<0,"Убыток","Прибыль / ноль") -> Прибыль / ноль | C18: =IF(C16<0,"Убыток","Прибыль / ноль") -> Убыток | D18: =IF(D16<0,"Убыток","Прибыль / ноль") -> Прибыль / ноль | E18: =IF(E16<0,"Убыток","Прибыль / ноль") -> Прибыль / ноль | F18: =IF(F16<0,"Убыток","Прибыль / ноль") -> Прибыль / ноль | G18: =IF(G16<0,"Убыток","Прибыль / ноль") -> Прибыль / ноль | H18: =IF(H16<0,"Убыток","Прибыль / ноль") -> Прибыль / ноль | I18: =IF(I16<0,"Убыток","Прибыль / ноль") -> Убыток | ... M18: =IF(M16<0,"Убыток","Прибыль / ноль") -> Прибыль / ноль | N18: =COUNTIF(B16:M16,"<0") -> 2

Sheet БАЛАНС
A1: Главная панель | D1: Настройки | F1: Контроль
A2: БАЛАНС
A3: LEO STUDIO • Управленческий учёт • RUB
A6: Статья | B6: Сумма | C6: Методика
A7: Денежные средства | B7: =СЧЕТА!B19 -> 1675043.2 | C7: Все счета, включая резерв
A8: Дебиторская задолженность | B8: =НАСТРОЙКИ!B36+SUMIFS(Docs[Остаток],Docs[Дата],"<="&ДатаОтчета,Docs[Статус],"Проведён",Docs[Тип долга],"ДЗ") -> 59040 | C8: Сумма непогашенных начислений
A9: Основные средства нетто | B9: =АКТИВЫ!B59 -> 125000 | C9: Стоимость минус амортизация
A10: Прочие активы | B10: =НАСТРОЙКИ!B38+MAX(0,-НАЛОГИ!J18)+MAX(0,НАЛОГИ!B26-НАЛОГИ!B25)+MAX(0,-НАЛОГИ!B30) -> 0 | C10: Начальные активы и налоговые переплаты
A11: АКТИВЫ | B11: =SUM(B7:B10) -> 1859083.2
A14: Кредиторская задолженность | B14: =НАСТРОЙКИ!B37+SUMIFS(Docs[Остаток],Docs[Дата],"<="&ДатаОтчета,Docs[Статус],"Проведён",Docs[Тип долга],"КЗ") -> 131200 | C14: Включает начисленные дивиденды
A15: Кредиты и займы | B15: =НАСТРОЙКИ!B33+SUMIFS(Cash[Поток],Cash[Дата],"<="&ДатаОтчета,Cash[Статус],"Проведён",Cash[Тип],"Получение кредита")+SUMIFS(Cash[Поток],Cash[Дата],"<="&ДатаОтчета,Cash[Статус],"Проведён",Cash[Тип],"Тело кредита")+SUMIFS(Cash[Поток],Cash[Дата],"<="&ДатаОтчета,Cash[Статус],"Проведён",Cash[Тип],"Займ участника")+SUMIFS(Cash[Поток],Cash[Дата],"<="&ДатаОтчета,Cash[Статус],"Проведён",Cash[Тип],"Возврат займа") -> 136028.15 | C15: Тело отдельно от процентов
A16: Налоги и взносы | B16: =MAX(0,НАЛОГИ!J18)+НАЛОГИ!B27+MAX(0,НАЛОГИ!B30) -> 319657.2 | C16: НДФЛ сотрудников уже в КЗ
A17: Прочие обязательства | B17: =НАСТРОЙКИ!B39 -> 0 | C17: Начальное сальдо
A18: ОБЯЗАТЕЛЬСТВА | B18: =SUM(B14:B17) -> 586885.35
A21: Начальный капитал | B21: =НАСТРОЙКИ!B32 -> 0 | C21: Явный ввод, не подгонка баланса
A22: Взносы собственников | B22: =SUMIFS(Cash[Поток],Cash[Дата],"<="&ДатаОтчета,Cash[Статус],"Проведён",Cash[Тип],"Взнос собственника") -> 500000 | C22: Для ООО: уставный капитал / вклад с документом
A23: Накопленный результат | B23: =НАСТРОЙКИ!B35+ОПиУ!N16 -> 872197.89 | C23: Начальная прибыль плюс результат года
A24: Изъятия / дивиденды | B24: =-SUMIFS(Cash[Поток],Cash[Дата],"<="&ДатаОтчета,Cash[Статус],"Проведён",Cash[Тип],"Вывод ИП")+SUMIFS(Docs[Сумма],Docs[Дата],"<="&ДатаОтчета,Docs[Статус],"Проведён",Docs[Вид],"Дивиденды") -> 100000 | C24: Уменьшение капитала, не расход
A25: КАПИТАЛ | B25: =B21+B22+B23-B24 -> 1272197.9
A27: Обязательства + капитал | B27: =B18+B25 -> 1859083.2
A28: Расхождение | B28: =B11-B27 -> 0 | C28: Если не ноль: проверьте начальные остатки, связи, активы
A29: Состояние | B29: =IF(ABS(B28)<0.02,"Баланс сходится","ОШИБКА: баланс не сходится") -> Баланс сходится

Sheet НАЛОГИ
A1: Главная панель | D1: Настройки | F1: Контроль
A2: НАЛОГИ
A3: LEO STUDIO • Управленческий учёт • RUB
A4: Область расчёта | B4: =IF(OR(AND(Форма<>"ИП",Форма<>"ООО"),AND(Режим<>"УСН Доходы",Режим<>"УСН Д-Р",Режим<>"НПД",Режим<>"Ручной")),"РУЧНОЙ: неизвестная форма или режим",IF(Год<>2026,"РУЧНОЙ: обновите правила года",IF(AND(Форма="ООО",Режим="НПД"),"ОШИБКА: ООО не вправе НПД",IF(Режим="Ручной","РУЧНОЙ РЕЖИМ",IF(AND(Режим="НПД",OR(Сотрудники="Да",НАСТРОЙКИ!B27<>"Да",SUM(Cash[Налоговый доход])>ЛимитНПД)),"РУЧНОЙ: условия НПД",IF(AND(Режим<>"НПД",OR(ДоходПрошлыйГод>ПорогНДС,SUM(Cash[Налоговый доход])>ПорогНДС)),"РУЧНОЙ: возникновение НДС",IF(НАСТРОЙКИ!B28<>"Да","РУЧНОЙ: запрет автоналога","ПРЕДВАРИТЕЛЬНЫЙ РАСЧЁТ"))))))) -> ПРЕДВАРИТЕЛЬНЫЙ РАСЧЁТ
A6: Месяц | B6: Доход ФЛ НИ | C6: Доход ЮЛ НИ | D6: Расход УСН НИ | E6: База Д-Р НИ | F6: Вычет взносов ввод | G6: Налог НИ | H6: Начислено месяц | I6: Уплачено месяц | J6: Налог сальдо | K6: Взносы ИП НИ | L6: Взносы ИП месяц | M6: НДС ввод | N6: Налог вручную
A7: =DATE(Год,1,1) -> 46023 | B7: =SUMIFS(Cash[Налоговый доход],Cash[Дата],">="&DATE(Год,1,1),Cash[Дата],"<="&MIN(EOMONTH(A7,0),ДатаОтчета),Cash[Тип лица],"ФЛ") -> 42000 | C7: =SUMIFS(Cash[Налоговый доход],Cash[Дата],">="&DATE(Год,1,1),Cash[Дата],"<="&MIN(EOMONTH(A7,0),ДатаОтчета),Cash[Тип лица],"<>ФЛ") -> 378000 | D7: =SUMIFS(Cash[Налоговый расход],Cash[Дата],">="&DATE(Год,1,1),Cash[Дата],"<="&MIN(EOMONTH(A7,0),ДатаОтчета),Cash[Статус],"Проведён",Cash[Тип],"<>Возврат поставщика")-SUMIFS(Cash[Налоговый расход],Cash[Дата],">="&DATE(Год,1,1),Cash[Дата],"<="&MIN(EOMONTH(A7,0),ДатаОтчета),Cash[Статус],"Проведён",Cash[Тип],"Возврат поставщика") -> 383900 | E7: =MAX(0,B7+C7-D7) -> 36100 | F7: 0 | G7: =IF(A7>ДатаОтчета,0,IF($B$4="ПРЕДВАРИТЕЛЬНЫЙ РАСЧЁТ",ROUND(IF(Режим="УСН Доходы",MAX(0,(B7+C7)*СтавкаДоход-IF(OR(Форма="ООО",Сотрудники="Да"),MIN((B7+C7)*СтавкаДоход*0.5,SUM($F$7:F7)+IF(MONTH(A7)=12,ВычетУСН,0)),MIN((B7+C7)*СтавкаДоход,SUM($F$7:F7)+IF(MONTH(A7)=12,ВычетУСН,0)))),IF(Режим="УСН Д-Р",MAX(E7*СтавкаДР,IF(MONTH(A7)=12,(B7+C7)*0.01,0)),MAX(0,B7*СтавкаНПДФЛ+C7*СтавкаНПДЮЛ-MIN(БонусНПД,B7*0.01+C7*0.02)))),2),SUM($N$7:N7))) -> 25200 | H7: =G7 -> 25200 | I7: =SUMIFS(Cash[Сумма],Cash[Дата],"<="&ДатаОтчета,Cash[Статус],"Проведён",Cash[Тип],"Налог",Cash[Дата],">="&A7,Cash[Дата],"<"&EDATE(A7,1),Cash[Категория],"<>НДС") -> 0 | J7: =НАСТРОЙКИ!$B$34+G7-SUM($I$7:I7) -> 25200 | K7: =IF(A7>ДатаОтчета,0,IF(AND(Форма="ИП",Режим<>"НПД",НАСТРОЙКИ!B28="Да"),IF(A7>ДатаОтчета,0,ФиксВзносы*MONTH(A7)/12+MIN(МаксВзносы,MAX(0,IF(Режим="УСН Д-Р",E7,B7+C7)-300000)*0.01)),0)) -> 5982.5 | L7: =K7 -> 5982.5 | M7: 0 | N7: 0
A8: =DATE(Год,2,1) -> 46054 | B8: =SUMIFS(Cash[Налоговый доход],Cash[Дата],">="&DATE(Год,1,1),Cash[Дата],"<="&MIN(EOMONTH(A8,0),ДатаОтчета),Cash[Тип лица],"ФЛ") -> 60000 | C8: =SUMIFS(Cash[Налоговый доход],Cash[Дата],">="&DATE(Год,1,1),Cash[Дата],"<="&MIN(EOMONTH(A8,0),ДатаОтчета),Cash[Тип лица],"<>ФЛ") -> 540000 | D8: =SUMIFS(Cash[Налоговый расход],Cash[Дата],">="&DATE(Год,1,1),Cash[Дата],"<="&MIN(EOMONTH(A8,0),ДатаОтчета),Cash[Статус],"Проведён",Cash[Тип],"<>Возврат поставщика")-SUMIFS(Cash[Налоговый расход],Cash[Дата],">="&DATE(Год,1,1),Cash[Дата],"<="&MIN(EOMONTH(A8,0),ДатаОтчета),Cash[Статус],"Проведён",Cash[Тип],"Возврат поставщика") -> 690842.84 | E8: =MAX(0,B8+C8-D8) -> 0 | F8: 0 | G8: =IF(A8>ДатаОтчета,G7,IF($B$4="ПРЕДВАРИТЕЛЬНЫЙ РАСЧЁТ",ROUND(IF(Режим="УСН Доходы",MAX(0,(B8+C8)*СтавкаДоход-IF(OR(Форма="ООО",Сотрудники="Да"),MIN((B8+C8)*СтавкаДоход*0.5,SUM($F$7:F8)+IF(MONTH(A8)=12,ВычетУСН,0)),MIN((B8+C8)*СтавкаДоход,SUM($F$7:F8)+IF(MONTH(A8)=12,ВычетУСН,0)))),IF(Режим="УСН Д-Р",MAX(E8*СтавкаДР,IF(MONTH(A8)=12,(B8+C8)*0.01,0)),MAX(0,B8*СтавкаНПДФЛ+C8*СтавкаНПДЮЛ-MIN(БонусНПД,B8*0.01+C8*0.02)))),2),SUM($N$7:N8))) -> 36000 | H8: =G8-G7 -> 10800 | I8: =SUMIFS(Cash[Сумма],Cash[Дата],"<="&ДатаОтчета,Cash[Статус],"Проведён",Cash[Тип],"Налог",Cash[Дата],">="&A8,Cash[Дата],"<"&EDATE(A8,1),Cash[Категория],"<>НДС") -> 0 | J8: =НАСТРОЙКИ!$B$34+G8-SUM($I$7:I8) -> 36000 | K8: =IF(A8>ДатаОтчета,K7,IF(AND(Форма="ИП",Режим<>"НПД",НАСТРОЙКИ!B28="Да"),IF(A8>ДатаОтчета,0,ФиксВзносы*MONTH(A8)/12+MIN(МаксВзносы,MAX(0,IF(Режим="УСН Д-Р",E8,B8+C8)-300000)*0.01)),0)) -> 12565 | L8: =K8-K7 -> 6582.5 | M8: 0 | N8: 0
A9: =DATE(Год,3,1) -> 46082 | B9: =SUMIFS(Cash[Налоговый доход],Cash[Дата],">="&DATE(Год,1,1),Cash[Дата],"<="&MIN(EOMONTH(A9,0),ДатаОтчета),Cash[Тип лица],"ФЛ") -> 111000 | C9: =SUMIFS(Cash[Налоговый доход],Cash[Дата],">="&DATE(Год,1,1),Cash[Дата],"<="&MIN(EOMONTH(A9,0),ДатаОтчета),Cash[Тип лица],"<>ФЛ") -> 996000 | D9: =SUMIFS(Cash[Налоговый расход],Cash[Дата],">="&DATE(Год,1,1),Cash[Дата],"<="&MIN(EOMONTH(A9,0),ДатаОтчета),Cash[Статус],"Проведён",Cash[Тип],"<>Возврат поставщика")-SUMIFS(Cash[Налоговый расход],Cash[Дата],">="&DATE(Год,1,1),Cash[Дата],"<="&MIN(EOMONTH(A9,0),ДатаОтчета),Cash[Статус],"Проведён",Cash[Тип],"Возврат поставщика") -> 1103226.2 | E9: =MAX(0,B9+C9-D9) -> 3773.83 | F9: 0 | G9: =IF(A9>ДатаОтчета,G8,IF($B$4="ПРЕДВАРИТЕЛЬНЫЙ РАСЧЁТ",ROUND(IF(Режим="УСН Доходы",MAX(0,(B9+C9)*СтавкаДоход-IF(OR(Форма="ООО",Сотрудники="Да"),MIN((B9+C9)*СтавкаДоход*0.5,SUM($F$7:F9)+IF(MONTH(A9)=12,ВычетУСН,0)),MIN((B9+C9)*СтавкаДоход,SUM($F$7:F9)+IF(MONTH(A9)=12,ВычетУСН,0)))),IF(Режим="УСН Д-Р",MAX(E9*СтавкаДР,IF(MONTH(A9)=12,(B9+C9)*0.01,0)),MAX(0,B9*СтавкаНПДФЛ+C9*СтавкаНПДЮЛ-MIN(БонусНПД,B9*0.01+C9*0.02)))),2),SUM($N$7:N9))) -> 66420 | H9: =G9-G8 -> 30420 | I9: =SUMIFS(Cash[Сумма],Cash[Дата],"<="&ДатаОтчета,Cash[Статус],"Проведён",Cash[Тип],"Налог",Cash[Дата],">="&A9,Cash[Дата],"<"&EDATE(A9,1),Cash[Категория],"<>НДС") -> 0 | J9: =НАСТРОЙКИ!$B$34+G9-SUM($I$7:I9) -> 66420 | K9: =IF(A9>ДатаОтчета,K8,IF(AND(Форма="ИП",Режим<>"НПД",НАСТРОЙКИ!B28="Да"),IF(A9>ДатаОтчета,0,ФиксВзносы*MONTH(A9)/12+MIN(МаксВзносы,MAX(0,IF(Режим="УСН Д-Р",E9,B9+C9)-300000)*0.01)),0)) -> 22417.5 | L9: =K9-K8 -> 9852.5 | M9: 0 | N9: 0
A10: =DATE(Год,4,1) -> 46113 | B10: =SUMIFS(Cash[Налоговый доход],Cash[Дата],">="&DATE(Год,1,1),Cash[Дата],"<="&MIN(EOMONTH(A10,0),ДатаОтчета),Cash[Тип лица],"ФЛ") -> 166000 | C10: =SUMIFS(Cash[Налоговый доход],Cash[Дата],">="&DATE(Год,1,1),Cash[Дата],"<="&MIN(EOMONTH(A10,0),ДатаОтчета),Cash[Тип лица],"<>ФЛ") -> 1491000 | D10: =SUMIFS(Cash[Налоговый расход],Cash[Дата],">="&DATE(Год,1,1),Cash[Дата],"<="&MIN(EOMONTH(A10,0),ДатаОтчета),Cash[Статус],"Проведён",Cash[Тип],"<>Возврат поставщика")-SUMIFS(Cash[Налоговый расход],Cash[Дата],">="&DATE(Год,1,1),Cash[Дата],"<="&MIN(EOMONTH(A10,0),ДатаОтчета),Cash[Статус],"Проведён",Cash[Тип],"Возврат поставщика") -> 1528247.6 | E10: =MAX(0,B10+C10-D10) -> 128752.41 | F10: 0 | G10: =IF(A10>ДатаОтчета,G9,IF($B$4="ПРЕДВАРИТЕЛЬНЫЙ РАСЧЁТ",ROUND(IF(Режим="УСН Доходы",MAX(0,(B10+C10)*СтавкаДоход-IF(OR(Форма="ООО",Сотрудники="Да"),MIN((B10+C10)*СтавкаДоход*0.5,SUM($F$7:F10)+IF(MONTH(A10)=12,ВычетУСН,0)),MIN((B10+C10)*СтавкаДоход,SUM($F$7:F10)+IF(MONTH(A10)=12,ВычетУСН,0)))),IF(Режим="УСН Д-Р",MAX(E10*СтавкаДР,IF(MONTH(A10)=12,(B10+C10)*0.01,0)),MAX(0,B10*СтавкаНПДФЛ+C10*СтавкаНПДЮЛ-MIN(БонусНПД,B10*0.01+C10*0.02)))),2),SUM($N$7:N10))) -> 99420 | H10: =G10-G9 -> 33000 | I10: =SUMIFS(Cash[Сумма],Cash[Дата],"<="&ДатаОтчета,Cash[Статус],"Проведён",Cash[Тип],"Налог",Cash[Дата],">="&A10,Cash[Дата],"<"&EDATE(A10,1),Cash[Категория],"<>НДС") -> 45000 | J10: =НАСТРОЙКИ!$B$34+G10-SUM($I$7:I10) -> 54420 | K10: =IF(A10>ДатаОтчета,K9,IF(AND(Форма="ИП",Режим<>"НПД",НАСТРОЙКИ!B28="Да"),IF(A10>ДатаОтчета,0,ФиксВзносы*MONTH(A10)/12+MIN(МаксВзносы,MAX(0,IF(Режим="УСН Д-Р",E10,B10+C10)-300000)*0.01)),0)) -> 32700 | L10: =K10-K9 -> 10282.5 | M10: 0 | N10: 0
A11: =DATE(Год,5,1) -> 46143 | B11: =SUMIFS(Cash[Налоговый доход],Cash[Дата],">="&DATE(Год,1,1),Cash[Дата],"<="&MIN(EOMONTH(A11,0),ДатаОтчета),Cash[Тип лица],"ФЛ") -> 224000 | C11: =SUMIFS(Cash[Налоговый доход],Cash[Дата],">="&DATE(Год,1,1),Cash[Дата],"<="&MIN(EOMONTH(A11,0),ДатаОтчета),Cash[Тип лица],"<>ФЛ") -> 2013000 | D11: =SUMIFS(Cash[Налоговый расход],Cash[Дата],">="&DATE(Год,1,1),Cash[Дата],"<="&MIN(EOMONTH(A11,0),ДатаОтчета),Cash[Статус],"Проведён",Cash[Тип],"<>Возврат поставщика")-SUMIFS(Cash[Налоговый расход],Cash[Дата],">="&DATE(Год,1,1),Cash[Дата],"<="&MIN(EOMONTH(A11,0),ДатаОтчета),Cash[Статус],"Проведён",Cash[Тип],"Возврат поставщика") -> 1962704.7 | E11: =MAX(0,B11+C11-D11) -> 274295.33 | F11: 0 | G11: =IF(A11>ДатаОтчета,G10,IF($B$4="ПРЕДВАРИТЕЛЬНЫЙ РАСЧЁТ",ROUND(IF(Режим="УСН Доходы",MAX(0,(B11+C11)*СтавкаДоход-IF(OR(Форма="ООО",Сотрудники="Да"),MIN((B11+C11)*СтавкаДоход*0.5,SUM($F$7:F11)+IF(MONTH(A11)=12,ВычетУСН,0)),MIN((B11+C11)*СтавкаДоход,SUM($F$7:F11)+IF(MONTH(A11)=12,ВычетУСН,0)))),IF(Режим="УСН Д-Р",MAX(E11*СтавкаДР,IF(MONTH(A11)=12,(B11+C11)*0.01,0)),MAX(0,B11*СтавкаНПДФЛ+C11*СтавкаНПДЮЛ-MIN(БонусНПД,B11*0.01+C11*0.02)))),2),SUM($N$7:N11))) -> 134220 | H11: =G11-G10 -> 34800 | I11: =SUMIFS(Cash[Сумма],Cash[Дата],"<="&ДатаОтчета,Cash[Статус],"Проведён",Cash[Тип],"Налог",Cash[Дата],">="&A11,Cash[Дата],"<"&EDATE(A11,1),Cash[Категория],"<>НДС") -> 0 | J11: =НАСТРОЙКИ!$B$34+G11-SUM($I$7:I11) -> 89220 | K11: =IF(A11>ДатаОтчета,K10,IF(AND(Форма="ИП",Режим<>"НПД",НАСТРОЙКИ!B28="Да"),IF(A11>ДатаОтчета,0,ФиксВзносы*MONTH(A11)/12+MIN(МаксВзносы,MAX(0,IF(Режим="УСН Д-Р",E11,B11+C11)-300000)*0.01)),0)) -> 43282.5 | L11: =K11-K10 -> 10582.5 | M11: 0 | N11: 0
A12: =DATE(Год,6,1) -> 46174 | B12: =SUMIFS(Cash[Налоговый доход],Cash[Дата],">="&DATE(Год,1,1),Cash[Дата],"<="&MIN(EOMONTH(A12,0),ДатаОтчета),Cash[Тип лица],"ФЛ") -> 286000 | C12: =SUMIFS(Cash[Налоговый доход],Cash[Дата],">="&DATE(Год,1,1),Cash[Дата],"<="&MIN(EOMONTH(A12,0),ДатаОтчета),Cash[Тип лица],"<>ФЛ") -> 2571000 | D12: =SUMIFS(Cash[Налоговый расход],Cash[Дата],">="&DATE(Год,1,1),Cash[Дата],"<="&MIN(EOMONTH(A12,0),ДатаОтчета),Cash[Статус],"Проведён",Cash[Тип],"<>Возврат поставщика")-SUMIFS(Cash[Налоговый расход],Cash[Дата],">="&DATE(Год,1,1),Cash[Дата],"<="&MIN(EOMONTH(A12,0),ДатаОтчета),Cash[Статус],"Проведён",Cash[Тип],"Возврат поставщика") -> 2409794.9 | E12: =MAX(0,B12+C12-D12) -> 447205.05 | F12: 0 | G12: =IF(A12>ДатаОтчета,G11,IF($B$4="ПРЕДВАРИТЕЛЬНЫЙ РАСЧЁТ",ROUND(IF(Режим="УСН Доходы",MAX(0,(B12+C12)*СтавкаДоход-IF(OR(Форма="ООО",Сотрудники="Да"),MIN((B12+C12)*СтавкаДоход*0.5,SUM($F$7:F12)+IF(MONTH(A12)=12,ВычетУСН,0)),MIN((B12+C12)*СтавкаДоход,SUM($F$7:F12)+IF(MONTH(A12)=12,ВычетУСН,0)))),IF(Режим="УСН Д-Р",MAX(E12*СтавкаДР,IF(MONTH(A12)=12,(B12+C12)*0.01,0)),MAX(0,B12*СтавкаНПДФЛ+C12*СтавкаНПДЮЛ-MIN(БонусНПД,B12*0.01+C12*0.02)))),2),SUM($N$7:N12))) -> 171420 | H12: =G12-G11 -> 37200 | I12: =SUMIFS(Cash[Сумма],Cash[Дата],"<="&ДатаОтчета,Cash[Статус],"Проведён",Cash[Тип],"Налог",Cash[Дата],">="&A12,Cash[Дата],"<"&EDATE(A12,1),Cash[Категория],"<>НДС") -> 0 | J12: =НАСТРОЙКИ!$B$34+G12-SUM($I$7:I12) -> 126420 | K12: =IF(A12>ДатаОтчета,K11,IF(AND(Форма="ИП",Режим<>"НПД",НАСТРОЙКИ!B28="Да"),IF(A12>ДатаОтчета,0,ФиксВзносы*MONTH(A12)/12+MIN(МаксВзносы,MAX(0,IF(Режим="УСН Д-Р",E12,B12+C12)-300000)*0.01)),0)) -> 54265 | L12: =K12-K11 -> 10982.5 | M12: 0 | N12: 0
A13: =DATE(Год,7,1) -> 46204 | B13: =SUMIFS(Cash[Налоговый доход],Cash[Дата],">="&DATE(Год,1,1),Cash[Дата],"<="&MIN(EOMONTH(A13,0),ДатаОтчета),Cash[Тип лица],"ФЛ") -> 345000 | C13: =SUMIFS(Cash[Налоговый доход],Cash[Дата],">="&DATE(Год,1,1),Cash[Дата],"<="&MIN(EOMONTH(A13,0),ДатаОтчета),Cash[Тип лица],"<>ФЛ") -> 3102000 | D13: =SUMIFS(Cash[Налоговый расход],Cash[Дата],">="&DATE(Год,1,1),Cash[Дата],"<="&MIN(EOMONTH(A13,0),ДатаОтчета),Cash[Статус],"Проведён",Cash[Тип],"<>Возврат поставщика")-SUMIFS(Cash[Налоговый расход],Cash[Дата],">="&DATE(Год,1,1),Cash[Дата],"<="&MIN(EOMONTH(A13,0),ДатаОтчета),Cash[Статус],"Проведён",Cash[Тип],"Возврат поставщика") -> 2846740.9 | E13: =MAX(0,B13+C13-D13) -> 600259.08 | F13: 0 | G13: =IF(A13>ДатаОтчета,G12,IF($B$4="ПРЕДВАРИТЕЛЬНЫЙ РАСЧЁТ",ROUND(IF(Режим="УСН Доходы",MAX(0,(B13+C13)*СтавкаДоход-IF(OR(Форма="ООО",Сотрудники="Да"),MIN((B13+C13)*СтавкаДоход*0.5,SUM($F$7:F13)+IF(MONTH(A13)=12,ВычетУСН,0)),MIN((B13+C13)*СтавкаДоход,SUM($F$7:F13)+IF(MONTH(A13)=12,ВычетУСН,0)))),IF(Режим="УСН Д-Р",MAX(E13*СтавкаДР,IF(MONTH(A13)=12,(B13+C13)*0.01,0)),MAX(0,B13*СтавкаНПДФЛ+C13*СтавкаНПДЮЛ-MIN(БонусНПД,B13*0.01+C13*0.02)))),2),SUM($N$7:N13))) -> 206820 | H13: =G13-G12 -> 35400 | I13: =SUMIFS(Cash[Сумма],Cash[Дата],"<="&ДатаОтчета,Cash[Статус],"Проведён",Cash[Тип],"Налог",Cash[Дата],">="&A13,Cash[Дата],"<"&EDATE(A13,1),Cash[Категория],"<>НДС") -> 45000 | J13: =НАСТРОЙКИ!$B$34+G13-SUM($I$7:I13) -> 116820 | K13: =IF(A13>ДатаОтчета,K12,IF(AND(Форма="ИП",Режим<>"НПД",НАСТРОЙКИ!B28="Да"),IF(A13>ДатаОтчета,0,ФиксВзносы*MONTH(A13)/12+MIN(МаксВзносы,MAX(0,IF(Режим="УСН Д-Р",E13,B13+C13)-300000)*0.01)),0)) -> 64947.5 | L13: =K13-K12 -> 10682.5 | M13: 0 | N13: 0
A14: =DATE(Год,8,1) -> 46235 | B14: =SUMIFS(Cash[Налоговый доход],Cash[Дата],">="&DATE(Год,1,1),Cash[Дата],"<="&MIN(EOMONTH(A14,0),ДатаОтчета),Cash[Тип лица],"ФЛ") -> 366000 | C14: =SUMIFS(Cash[Налоговый доход],Cash[Дата],">="&DATE(Год,1,1),Cash[Дата],"<="&MIN(EOMONTH(A14,0),ДатаОтчета),Cash[Тип лица],"<>ФЛ") -> 3291000 | D14: =SUMIFS(Cash[Налоговый расход],Cash[Дата],">="&DATE(Год,1,1),Cash[Дата],"<="&MIN(EOMONTH(A14,0),ДатаОтчета),Cash[Статус],"Проведён",Cash[Тип],"<>Возврат поставщика")-SUMIFS(Cash[Налоговый расход],Cash[Дата],">="&DATE(Год,1,1),Cash[Дата],"<="&MIN(EOMONTH(A14,0),ДатаОтчета),Cash[Статус],"Проведён",Cash[Тип],"Возврат поставщика") -> 3226909.4 | E14: =MAX(0,B14+C14-D14) -> 430090.58 | F14: 0 | G14: =IF(A14>ДатаОтчета,G13,IF($B$4="ПРЕДВАРИТЕЛЬНЫЙ РАСЧЁТ",ROUND(IF(Режим="УСН Доходы",MAX(0,(B14+C14)*СтавкаДоход-IF(OR(Форма="ООО",Сотрудники="Да"),MIN((B14+C14)*СтавкаДоход*0.5,SUM($F$7:F14)+IF(MONTH(A14)=12,ВычетУСН,0)),MIN((B14+C14)*СтавкаДоход,SUM($F$7:F14)+IF(MONTH(A14)=12,ВычетУСН,0)))),IF(Режим="УСН Д-Р",MAX(E14*СтавкаДР,IF(MONTH(A14)=12,(B14+C14)*0.01,0)),MAX(0,B14*СтавкаНПДФЛ+C14*СтавкаНПДЮЛ-MIN(БонусНПД,B14*0.01+C14*0.02)))),2),SUM($N$7:N14))) -> 219420 | H14: =G14-G13 -> 12600 | I14: =SUMIFS(Cash[Сумма],Cash[Дата],"<="&ДатаОтчета,Cash[Статус],"Проведён",Cash[Тип],"Налог",Cash[Дата],">="&A14,Cash[Дата],"<"&EDATE(A14,1),Cash[Категория],"<>НДС") -> 0 | J14: =НАСТРОЙКИ!$B$34+G14-SUM($I$7:I14) -> 129420 | K14: =IF(A14>ДатаОтчета,K13,IF(AND(Форма="ИП",Режим<>"НПД",НАСТРОЙКИ!B28="Да"),IF(A14>ДатаОтчета,0,ФиксВзносы*MONTH(A14)/12+MIN(МаксВзносы,MAX(0,IF(Режим="УСН Д-Р",E14,B14+C14)-300000)*0.01)),0)) -> 71830 | L14: =K14-K13 -> 6882.5 | M14: 0 | N14: 0
A15: =DATE(Год,9,1) -> 46266 | B15: =SUMIFS(Cash[Налоговый доход],Cash[Дата],">="&DATE(Год,1,1),Cash[Дата],"<="&MIN(EOMONTH(A15,0),ДатаОтчета),Cash[Тип лица],"ФЛ") -> 431000 | C15: =SUMIFS(Cash[Налоговый доход],Cash[Дата],">="&DATE(Год,1,1),Cash[Дата],"<="&MIN(EOMONTH(A15,0),ДатаОтчета),Cash[Тип лица],"<>ФЛ") -> 3876000 | D15: =SUMIFS(Cash[Налоговый расход],Cash[Дата],">="&DATE(Год,1,1),Cash[Дата],"<="&MIN(EOMONTH(A15,0),ДатаОтчета),Cash[Статус],"Проведён",Cash[Тип],"<>Возврат поставщика")-SUMIFS(Cash[Налоговый расход],Cash[Дата],">="&DATE(Год,1,1),Cash[Дата],"<="&MIN(EOMONTH(A15,0),ДатаОтчета),Cash[Статус],"Проведён",Cash[Тип],"Возврат поставщика") -> 3682697.8 | E15: =MAX(0,B15+C15-D15) -> 624302.21 | F15: 0 | G15: =IF(A15>ДатаОтчета,G14,IF($B$4="ПРЕДВАРИТЕЛЬНЫЙ РАСЧЁТ",ROUND(IF(Режим="УСН Доходы",MAX(0,(B15+C15)*СтавкаДоход-IF(OR(Форма="ООО",Сотрудники="Да"),MIN((B15+C15)*СтавкаДоход*0.5,SUM($F$7:F15)+IF(MONTH(A15)=12,ВычетУСН,0)),MIN((B15+C15)*СтавкаДоход,SUM($F$7:F15)+IF(MONTH(A15)=12,ВычетУСН,0)))),IF(Режим="УСН Д-Р",MAX(E15*СтавкаДР,IF(MONTH(A15)=12,(B15+C15)*0.01,0)),MAX(0,B15*СтавкаНПДФЛ+C15*СтавкаНПДЮЛ-MIN(БонусНПД,B15*0.01+C15*0.02)))),2),SUM($N$7:N15))) -> 258420 | H15: =G15-G14 -> 39000 | I15: =SUMIFS(Cash[Сумма],Cash[Дата],"<="&ДатаОтчета,Cash[Статус],"Проведён",Cash[Тип],"Налог",Cash[Дата],">="&A15,Cash[Дата],"<"&EDATE(A15,1),Cash[Категория],"<>НДС") -> 0 | J15: =НАСТРОЙКИ!$B$34+G15-SUM($I$7:I15) -> 168420 | K15: =IF(A15>ДатаОтчета,K14,IF(AND(Форма="ИП",Режим<>"НПД",НАСТРОЙКИ!B28="Да"),IF(A15>ДатаОтчета,0,ФиксВзносы*MONTH(A15)/12+MIN(МаксВзносы,MAX(0,IF(Режим="УСН Д-Р",E15,B15+C15)-300000)*0.01)),0)) -> 83112.5 | L15: =K15-K14 -> 11282.5 | M15: 0 | N15: 0
A16: =DATE(Год,10,1) -> 46296 | B16: =SUMIFS(Cash[Налоговый доход],Cash[Дата],">="&DATE(Год,1,1),Cash[Дата],"<="&MIN(EOMONTH(A16,0),ДатаОтчета),Cash[Тип лица],"ФЛ") -> 502000 | C16: =SUMIFS(Cash[Налоговый доход],Cash[Дата],">="&DATE(Год,1,1),Cash[Дата],"<="&MIN(EOMONTH(A16,0),ДатаОтчета),Cash[Тип лица],"<>ФЛ") -> 4515000 | D16: =SUMIFS(Cash[Налоговый расход],Cash[Дата],">="&DATE(Год,1,1),Cash[Дата],"<="&MIN(EOMONTH(A16,0),ДатаОтчета),Cash[Статус],"Проведён",Cash[Тип],"<>Возврат поставщика")-SUMIFS(Cash[Налоговый расход],Cash[Дата],">="&DATE(Год,1,1),Cash[Дата],"<="&MIN(EOMONTH(A16,0),ДатаОтчета),Cash[Статус],"Проведён",Cash[Тип],"Возврат поставщика") -> 4157503.3 | E16: =MAX(0,B16+C16-D16) -> 859496.67 | F16: 0 | G16: =IF(A16>ДатаОтчета,G15,IF($B$4="ПРЕДВАРИТЕЛЬНЫЙ РАСЧЁТ",ROUND(IF(Режим="УСН Доходы",MAX(0,(B16+C16)*СтавкаДоход-IF(OR(Форма="ООО",Сотрудники="Да"),MIN((B16+C16)*СтавкаДоход*0.5,SUM($F$7:F16)+IF(MONTH(A16)=12,ВычетУСН,0)),MIN((B16+C16)*СтавкаДоход,SUM($F$7:F16)+IF(MONTH(A16)=12,ВычетУСН,0)))),IF(Режим="УСН Д-Р",MAX(E16*СтавкаДР,IF(MONTH(A16)=12,(B16+C16)*0.01,0)),MAX(0,B16*СтавкаНПДФЛ+C16*СтавкаНПДЮЛ-MIN(БонусНПД,B16*0.01+C16*0.02)))),2),SUM($N$7:N16))) -> 301020 | H16: =G16-G15 -> 42600 | I16: =SUMIFS(Cash[Сумма],Cash[Дата],"<="&ДатаОтчета,Cash[Статус],"Проведён",Cash[Тип],"Налог",Cash[Дата],">="&A16,Cash[Дата],"<"&EDATE(A16,1),Cash[Категория],"<>НДС") -> 45000 | J16: =НАСТРОЙКИ!$B$34+G16-SUM($I$7:I16) -> 166020 | K16: =IF(A16>ДатаОтчета,K15,IF(AND(Форма="ИП",Режим<>"НПД",НАСТРОЙКИ!B28="Да"),IF(A16>ДатаОтчета,0,ФиксВзносы*MONTH(A16)/12+MIN(МаксВзносы,MAX(0,IF(Режим="УСН Д-Р",E16,B16+C16)-300000)*0.01)),0)) -> 94995 | L16: =K16-K15 -> 11882.5 | M16: 0 | N16: 0
A17: =DATE(Год,11,1) -> 46327 | B17: =SUMIFS(Cash[Налоговый доход],Cash[Дата],">="&DATE(Год,1,1),Cash[Дата],"<="&MIN(EOMONTH(A17,0),ДатаОтчета),Cash[Тип лица],"ФЛ") -> 578000 | C17: =SUMIFS(Cash[Налоговый доход],Cash[Дата],">="&DATE(Год,1,1),Cash[Дата],"<="&MIN(EOMONTH(A17,0),ДатаОтчета),Cash[Тип лица],"<>ФЛ") -> 5199000 | D17: =SUMIFS(Cash[Налоговый расход],Cash[Дата],">="&DATE(Год,1,1),Cash[Дата],"<="&MIN(EOMONTH(A17,0),ДатаОтчета),Cash[Статус],"Проведён",Cash[Тип],"<>Возврат поставщика")-SUMIFS(Cash[Налоговый расход],Cash[Дата],">="&DATE(Год,1,1),Cash[Дата],"<="&MIN(EOMONTH(A17,0),ДатаОтчета),Cash[Статус],"Проведён",Cash[Тип],"Возврат поставщика") -> 4648123.3 | E17: =MAX(0,B17+C17-D17) -> 1128876.7 | F17: 0 | G17: =IF(A17>ДатаОтчета,G16,IF($B$4="ПРЕДВАРИТЕЛЬНЫЙ РАСЧЁТ",ROUND(IF(Режим="УСН Доходы",MAX(0,(B17+C17)*СтавкаДоход-IF(OR(Форма="ООО",Сотрудники="Да"),MIN((B17+C17)*СтавкаДоход*0.5,SUM($F$7:F17)+IF(MONTH(A17)=12,ВычетУСН,0)),MIN((B17+C17)*СтавкаДоход,SUM($F$7:F17)+IF(MONTH(A17)=12,ВычетУСН,0)))),IF(Режим="УСН Д-Р",MAX(E17*СтавкаДР,IF(MONTH(A17)=12,(B17+C17)*0.01,0)),MAX(0,B17*СтавкаНПДФЛ+C17*СтавкаНПДЮЛ-MIN(БонусНПД,B17*0.01+C17*0.02)))),2),SUM($N$7:N17))) -> 346620 | H17: =G17-G16 -> 45600 | I17: =SUMIFS(Cash[Сумма],Cash[Дата],"<="&ДатаОтчета,Cash[Статус],"Проведён",Cash[Тип],"Налог",Cash[Дата],">="&A17,Cash[Дата],"<"&EDATE(A17,1),Cash[Категория],"<>НДС") -> 0 | J17: =НАСТРОЙКИ!$B$34+G17-SUM($I$7:I17) -> 211620 | K17: =IF(A17>ДатаОтчета,K16,IF(AND(Форма="ИП",Режим<>"НПД",НАСТРОЙКИ!B28="Да"),IF(A17>ДатаОтчета,0,ФиксВзносы*MONTH(A17)/12+MIN(МаксВзносы,MAX(0,IF(Режим="УСН Д-Р",E17,B17+C17)-300000)*0.01)),0)) -> 107377.5 | L17: =K17-K16 -> 12382.5 | M17: 0 | N17: 0
A18: =DATE(Год,12,1) -> 46357 | B18: =SUMIFS(Cash[Налоговый доход],Cash[Дата],">="&DATE(Год,1,1),Cash[Дата],"<="&MIN(EOMONTH(A18,0),ДатаОтчета),Cash[Тип лица],"ФЛ") -> 627200 | C18: =SUMIFS(Cash[Налоговый доход],Cash[Дата],">="&DATE(Год,1,1),Cash[Дата],"<="&MIN(EOMONTH(A18,0),ДатаОтчета),Cash[Тип лица],"<>ФЛ") -> 5910760 | D18: =SUMIFS(Cash[Налоговый расход],Cash[Дата],">="&DATE(Год,1,1),Cash[Дата],"<="&MIN(EOMONTH(A18,0),ДатаОтчета),Cash[Статус],"Проведён",Cash[Тип],"<>Возврат поставщика")-SUMIFS(Cash[Налоговый расход],Cash[Дата],">="&DATE(Год,1,1),Cash[Дата],"<="&MIN(EOMONTH(A18,0),ДатаОтчета),Cash[Статус],"Проведён",Cash[Тип],"Возврат поставщика") -> 5026554.9 | E18: =MAX(0,B18+C18-D18) -> 1511405.1 | F18: 0 | G18: =IF(A18>ДатаОтчета,G17,IF($B$4="ПРЕДВАРИТЕЛЬНЫЙ РАСЧЁТ",ROUND(IF(Режим="УСН Доходы",MAX(0,(B18+C18)*СтавкаДоход-IF(OR(Форма="ООО",Сотрудники="Да"),MIN((B18+C18)*СтавкаДоход*0.5,SUM($F$7:F18)+IF(MONTH(A18)=12,ВычетУСН,0)),MIN((B18+C18)*СтавкаДоход,SUM($F$7:F18)+IF(MONTH(A18)=12,ВычетУСН,0)))),IF(Режим="УСН Д-Р",MAX(E18*СтавкаДР,IF(MONTH(A18)=12,(B18+C18)*0.01,0)),MAX(0,B18*СтавкаНПДФЛ+C18*СтавкаНПДЮЛ-MIN(БонусНПД,B18*0.01+C18*0.02)))),2),SUM($N$7:N18))) -> 392277.6 | H18: =G18-G17 -> 45657.6 | I18: =SUMIFS(Cash[Сумма],Cash[Дата],"<="&ДатаОтчета,Cash[Статус],"Проведён",Cash[Тип],"Налог",Cash[Дата],">="&A18,Cash[Дата],"<"&EDATE(A18,1),Cash[Категория],"<>НДС") -> 0 | J18: =НАСТРОЙКИ!$B$34+G18-SUM($I$7:I18) -> 257277.6 | K18: =IF(A18>ДатаОтчета,K17,IF(AND(Форма="ИП",Режим<>"НПД",НАСТРОЙКИ!B28="Да"),IF(A18>ДатаОтчета,0,ФиксВзносы*MONTH(A18)/12+MIN(МаксВзносы,MAX(0,IF(Режим="УСН Д-Р",E18,B18+C18)-300000)*0.01)),0)) -> 119769.6 | L18: =K18-K17 -> 12392.1 | M18: 0 | N18: 0
A21: Предварительный налог | B21: =G18 -> 392277.6
A22: Уплачено налогов | B22: =SUM(I7:I18) -> 135000
A23: Налог к уплате | B23: =MAX(0,J18) -> 257277.6
A24: Переплата налога | B24: =MAX(0,-J18) -> 0
A25: Взносы ИП начислено | B25: =K18 -> 119769.6
A26: Взносы ИП уплачено | B26: =SUMIFS(Cash[Сумма],Cash[Дата],"<="&ДатаОтчета,Cash[Статус],"Проведён",Cash[Тип],"Взносы ИП") -> 57390
A27: Взносы ИП к уплате | B27: =MAX(0,B25-B26) -> 62379.6
A28: НДС начислено вручную | B28: =SUM(M7:M18) -> 0
A29: НДС уплачено | B29: =SUMIFS(Cash[Сумма],Cash[Дата],"<="&ДатаОтчета,Cash[Статус],"Проведён",Cash[Тип],"Налог",Cash[Категория],"НДС") -> 0
A30: НДС сальдо | B30: =B28-B29 -> 0
A31: Налоговая нагрузка | B31: =IF(SUM(B18:C18)=0,"н/д",(B21+B25+B28)/SUM(B18:C18)) -> 0.078319109
A34: Параметр | B34: Значение | C34: Год | D34: Проверено | E34: Условия | F34: Источник
A35: УСН доходы | B35: =НАСТРОЙКИ!B14 -> 0.06 | C35: 2026 | D35: 46310 | E35: Базовая / региональная ставка | F35: https://www.nalog.gov.ru/rn77/taxation/taxes/usn/
A36: УСН Д-Р | B36: =НАСТРОЙКИ!B15 -> 0.15 | C36: 2026 | D36: 46310 | E36: Минимальный 1% только по итогам года | F36: https://www.nalog.gov.ru/rn77/taxation/taxes/usn/
A37: НПД ФЛ | B37: =НАСТРОЙКИ!B16 -> 0.04 | C37: 2026 | D37: 46310 | E37: ФЛ, без запрещённых операций | F37: https://npd.nalog.ru/
A38: НПД ЮЛ | B38: =НАСТРОЙКИ!B17 -> 0.06 | C38: 2026 | D38: 46310 | E38: ЮЛ и ИП | F38: https://npd.nalog.ru/
A39: Лимит НПД | B39: 2400000 | C39: 2026 | D39: 46310 | E39: Годовой доход | F39: https://npd.nalog.ru/
A40: Порог НДС УСН | B40: 20000000 | C40: 2026 | D40: 46310 | E40: За прошлый или текущий год | F40: https://www.nalog.gov.ru/new2026/
A41: Лимит УСН 2026 | B41: 490500000 | C41: 2026 | D41: 46310 | E41: Дополнительно проверьте иные условия | F41: https://www.nalog.gov.ru/new2026/
A42: Взносы ИП | B42: =ФиксВзносы -> 57390 | C42: 2026 | D42: 46310 | E42: Полный год; отдельные категории исключены | F42: https://nalog.garant.ru/fns/nk/25251f9c341b4b29fabf5cb7957c5992/
A43: Доп. взносы максимум | B43: =МаксВзносы -> 321818 | C43: 2026 | D43: 46310 | E43: Совокупно 379208 с фиксированной частью | F43: https://nalog.garant.ru/fns/nk/25251f9c341b4b29fabf5cb7957c5992/
A46: Платёж | B46: Базовый срок | C46: Сумма план | D46: Примечание
A47: УСН 3 мес. | B47: =DATE(Год,4,28) -> 46140 | C47: =MAX(0,G9-SUM($I$7:I9)) -> 66420 | D47: Срок без переноса выходных; платёж сверить с ЕНС
...

Sheet БЮДЖЕТ
A1: Главная панель | D1: Настройки | F1: Контроль
A2: БЮДЖЕТ
A3: LEO STUDIO • Управленческий учёт • RUB
A6: Показатель | B6: =DATE(Год,1,1) -> 46023 | C6: =DATE(Год,2,1) -> 46054 | D6: =DATE(Год,3,1) -> 46082 | E6: =DATE(Год,4,1) -> 46113 | F6: =DATE(Год,5,1) -> 46143 | G6: =DATE(Год,6,1) -> 46174 | H6: =DATE(Год,7,1) -> 46204 | I6: =DATE(Год,8,1) -> 46235 | J6: =DATE(Год,9,1) -> 46266 | K6: =DATE(Год,10,1) -> 46296 | L6: =DATE(Год,11,1) -> 46327 | M6: =DATE(Год,12,1) -> 46357 | N6: Год / итог
A7: Выручка план | B7: 540000 | C7: 540000 | D7: 540000 | E7: 540000 | F7: 540000 | G7: 540000 | H7: 540000 | I7: 540000 | J7: 540000 | K7: 540000 | L7: 540000 | M7: 540000 | N7: =SUM(B7:M7) -> 6480000
A8: Себестоимость план | B8: 175000 | C8: 175000 | D8: 175000 | E8: 175000 | F8: 175000 | G8: 175000 | H8: 175000 | I8: 175000 | J8: 175000 | K8: 175000 | L8: 175000 | M8: 175000 | N8: =SUM(B8:M8) -> 2100000
A9: Операционные план | B9: 260000 | C9: 260000 | D9: 260000 | E9: 260000 | F9: 260000 | G9: 260000 | H9: 260000 | I9: 260000 | J9: 260000 | K9: 260000 | L9: 260000 | M9: 260000 | N9: =SUM(B9:M9) -> 3120000
A10: Налог + взносы ИП план | B10: 30000 | C10: 30000 | D10: 30000 | E10: 30000 | F10: 30000 | G10: 30000 | H10: 30000 | I10: 30000 | J10: 30000 | K10: 30000 | L10: 30000 | M10: 30000 | N10: =SUM(B10:M10) -> 360000
A11: Капитальные затраты план | B11: 180000 | C11: 0 | D11: 0 | E11: 0 | F11: 0 | G11: 0 | H11: 0 | I11: 0 | J11: 0 | K11: 0 | L11: 0 | M11: 0 | N11: =SUM(B11:M11) -> 180000
A12: Кредит: тело + проценты план | B12: 15000 | C12: 15000 | D12: 15000 | E12: 15000 | F12: 15000 | G12: 15000 | H12: 15000 | I12: 15000 | J12: 15000 | K12: 15000 | L12: 15000 | M12: 15000 | N12: =SUM(B12:M12) -> 180000
A13: Денежные поступления план | B13: 530000 | C13: 530000 | D13: 530000 | E13: 530000 | F13: 530000 | G13: 530000 | H13: 530000 | I13: 530000 | J13: 530000 | K13: 530000 | L13: 530000 | M13: 530000 | N13: =SUM(B13:M13) -> 6360000
A14: Денежные выплаты план | B14: 470000 | C14: 470000 | D14: 470000 | E14: 470000 | F14: 470000 | G14: 470000 | H14: 470000 | I14: 470000 | J14: 470000 | K14: 470000 | L14: 470000 | M14: 470000 | N14: =SUM(B14:M14) -> 5640000
A15: Денежный остаток план | B15: =SUM(Accounts[Начальный])+B13-B14 -> 60000 | C15: =B15+C13-C14 -> 120000 | D15: =C15+D13-D14 -> 180000 | E15: =D15+E13-E14 -> 240000 | F15: =E15+F13-F14 -> 300000 | G15: =F15+G13-G14 -> 360000 | H15: =G15+H13-H14 -> 420000 | I15: =H15+I13-I14 -> 480000 | J15: =I15+J13-J14 -> 540000 | ... M15: =L15+M13-M14 -> 720000 | N15: =M15 -> 720000
A18: Выручка факт | B18: =ОПиУ!B7 -> 420000 | C18: =ОПиУ!C7 -> 180000 | D18: =ОПиУ!D7 -> 507000 | E18: =ОПиУ!E7 -> 550000 | F18: =ОПиУ!F7 -> 580000 | G18: =ОПиУ!G7 -> 620000 | H18: =ОПиУ!H7 -> 590000 | I18: =ОПиУ!I7 -> 210000 | ... M18: =ОПиУ!M7 -> 820000 | N18: =SUM(B18:M18) -> 6597000
A19: Выручка отклонение, руб. | B19: =B18-B7 -> -120000 | C19: =C18-C7 -> -360000 | D19: =D18-D7 -> -33000 | E19: =E18-E7 -> 10000 | F19: =F18-F7 -> 40000 | G19: =G18-G7 -> 80000 | H19: =H18-H7 -> 50000 | I19: =I18-I7 -> -330000 | ... M19: =M18-M7 -> 280000 | N19: =SUM(B19:M19) -> 117000
A20: Выручка отклонение, % | B20: =IF(B7=0,"н/д",B19/B7) -> -0.22222222 | C20: =IF(C7=0,"н/д",C19/C7) -> -0.66666667 | D20: =IF(D7=0,"н/д",D19/D7) -> -0.061111111 | E20: =IF(E7=0,"н/д",E19/E7) -> 0.018518519 | F20: =IF(F7=0,"н/д",F19/F7) -> 0.074074074 | G20: =IF(G7=0,"н/д",G19/G7) -> 0.14814815 | H20: =IF(H7=0,"н/д",H19/H7) -> 0.092592593 | I20: =IF(I7=0,"н/д",I19/I7) -> -0.61111111 | ... N20: =IF(N7=0,"н/д",N19/N7) -> 0.018055556
